 * Serving Flask app "runBackend" (lazy loading)
 * Environment: production
   WARNING: This is a development server. Do not use it in a production deployment.
   Use a production WSGI server instead.
 * Debug mode: off
 * Running on http://0.0.0.0:5000/ (Press CTRL+C to quit)
130.44.64.227 - - [18/Feb/2021 17:17:44] "[37mGET /getUser HTTP/1.1[0m" 200 -
130.44.64.227 - - [18/Feb/2021 17:17:51] "[37mGET /getUser HTTP/1.1[0m" 200 -
130.44.64.227 - - [18/Feb/2021 17:18:03] "[37mGET /getUser HTTP/1.1[0m" 200 -
204.144.15.24 - - [18/Feb/2021 17:20:51] "[37mGET /getUser HTTP/1.1[0m" 200 -
[2021-02-18 17:21:05,401] ERROR in app: Exception on /addUser [POST]
Traceback (most recent call last):
  File "/root/green2go/Backend/userDao.py", line 23, in addUser
    mycursor.execute(sql, val)
  File "/usr/local/lib/python3.6/dist-packages/mysql/connector/cursor.py", line 551, in execute
    self._handle_result(self._connection.cmd_query(stmt))
  File "/usr/local/lib/python3.6/dist-packages/mysql/connector/connection.py", line 490, in cmd_query
    result = self._handle_result(self._send_cmd(ServerCmd.QUERY, query))
  File "/usr/local/lib/python3.6/dist-packages/mysql/connector/connection.py", line 395, in _handle_result
    raise errors.get_exception(packet)
mysql.connector.errors.DataError: 1292 (22007): Incorrect datetime value: '' for column 'authTime' at row 1

During handling of the above exception, another exception occurred:

Traceback (most recent call last):
  File "/root/green2go/Backend/userDao.py", line 23, in addUser
    mycursor.execute(sql, val)
  File "/usr/local/lib/python3.6/dist-packages/mysql/connector/cursor.py", line 551, in execute
    self._handle_result(self._connection.cmd_query(stmt))
  File "/usr/local/lib/python3.6/dist-packages/mysql/connector/connection.py", line 490, in cmd_query
    result = self._handle_result(self._send_cmd(ServerCmd.QUERY, query))
  File "/usr/local/lib/python3.6/dist-packages/mysql/connector/connection.py", line 395, in _handle_result
    raise errors.get_exception(packet)
mysql.connector.errors.DataError: 1292 (22007): Incorrect datetime value: '' for column 'authTime' at row 1

During handling of the above exception, another exception occurred:

Traceback (most recent call last):
  File "/root/green2go/Backend/userDao.py", line 23, in addUser
    mycursor.execute(sql, val)
  File "/usr/local/lib/python3.6/dist-packages/mysql/connector/cursor.py", line 551, in execute
    self._handle_result(self._connection.cmd_query(stmt))
  File "/usr/local/lib/python3.6/dist-packages/mysql/connector/connection.py", line 490, in cmd_query
    result = self._handle_result(self._send_cmd(ServerCmd.QUERY, query))
  File "/usr/local/lib/python3.6/dist-packages/mysql/connector/connection.py", line 395, in _handle_result
    raise errors.get_exception(packet)
mysql.connector.errors.DataError: 1292 (22007): Incorrect datetime value: '' for column 'authTime' at row 1

During handling of the above exception, another exception occurred:

Traceback (most recent call last):
  File "/root/green2go/Backend/userDao.py", line 23, in addUser
    mycursor.execute(sql, val)
  File "/usr/local/lib/python3.6/dist-packages/mysql/connector/cursor.py", line 551, in execute
    self._handle_result(self._connection.cmd_query(stmt))
  File "/usr/local/lib/python3.6/dist-packages/mysql/connector/connection.py", line 490, in cmd_query
    result = self._handle_result(self._send_cmd(ServerCmd.QUERY, query))
  File "/usr/local/lib/python3.6/dist-packages/mysql/connector/connection.py", line 395, in _handle_result
    raise errors.get_exception(packet)
mysql.connector.errors.DataError: 1292 (22007): Incorrect datetime value: '' for column 'authTime' at row 1

During handling of the above exception, another exception occurred:

Traceback (most recent call last):
  File "/root/green2go/Backend/userDao.py", line 23, in addUser
    mycursor.execute(sql, val)
  File "/usr/local/lib/python3.6/dist-packages/mysql/connector/cursor.py", line 551, in execute
    self._handle_result(self._connection.cmd_query(stmt))
  File "/usr/local/lib/python3.6/dist-packages/mysql/connector/connection.py", line 490, in cmd_query
    result = self._handle_result(self._send_cmd(ServerCmd.QUERY, query))
  File "/usr/local/lib/python3.6/dist-packages/mysql/connector/connection.py", line 395, in _handle_result
    raise errors.get_exception(packet)
mysql.connector.errors.DataError: 1292 (22007): Incorrect datetime value: '' for column 'authTime' at row 1

During handling of the above exception, another exception occurred:

Traceback (most recent call last):
  File "/root/green2go/Backend/userDao.py", line 23, in addUser
    mycursor.execute(sql, val)
  File "/usr/local/lib/python3.6/dist-packages/mysql/connector/cursor.py", line 551, in execute
    self._handle_result(self._connection.cmd_query(stmt))
  File "/usr/local/lib/python3.6/dist-packages/mysql/connector/connection.py", line 490, in cmd_query
    result = self._handle_result(self._send_cmd(ServerCmd.QUERY, query))
  File "/usr/local/lib/python3.6/dist-packages/mysql/connector/connection.py", line 395, in _handle_result
    raise errors.get_exception(packet)
mysql.connector.errors.DataError: 1292 (22007): Incorrect datetime value: '' for column 'authTime' at row 1

During handling of the above exception, another exception occurred:

Traceback (most recent call last):
  File "/root/green2go/Backend/userDao.py", line 23, in addUser
    mycursor.execute(sql, val)
  File "/usr/local/lib/python3.6/dist-packages/mysql/connector/cursor.py", line 551, in execute
    self._handle_result(self._connection.cmd_query(stmt))
  File "/usr/local/lib/python3.6/dist-packages/mysql/connector/connection.py", line 490, in cmd_query
    result = self._handle_result(self._send_cmd(ServerCmd.QUERY, query))
  File "/usr/local/lib/python3.6/dist-packages/mysql/connector/connection.py", line 395, in _handle_result
    raise errors.get_exception(packet)
mysql.connector.errors.DataError: 1292 (22007): Incorrect datetime value: '' for column 'authTime' at row 1

During handling of the above exception, another exception occurred:

Traceback (most recent call last):
  File "/root/green2go/Backend/userDao.py", line 23, in addUser
    mycursor.execute(sql, val)
  File "/usr/local/lib/python3.6/dist-packages/mysql/connector/cursor.py", line 551, in execute
    self._handle_result(self._connection.cmd_query(stmt))
  File "/usr/local/lib/python3.6/dist-packages/mysql/connector/connection.py", line 490, in cmd_query
    result = self._handle_result(self._send_cmd(ServerCmd.QUERY, query))
  File "/usr/local/lib/python3.6/dist-packages/mysql/connector/connection.py", line 395, in _handle_result
    raise errors.get_exception(packet)
mysql.connector.errors.DataError: 1292 (22007): Incorrect datetime value: '' for column 'authTime' at row 1

During handling of the above exception, another exception occurred:

Traceback (most recent call last):
  File "/root/green2go/Backend/userDao.py", line 23, in addUser
    mycursor.execute(sql, val)
  File "/usr/local/lib/python3.6/dist-packages/mysql/connector/cursor.py", line 551, in execute
    self._handle_result(self._connection.cmd_query(stmt))
  File "/usr/local/lib/python3.6/dist-packages/mysql/connector/connection.py", line 490, in cmd_query
    result = self._handle_result(self._send_cmd(ServerCmd.QUERY, query))
  File "/usr/local/lib/python3.6/dist-packages/mysql/connector/connection.py", line 395, in _handle_result
    raise errors.get_exception(packet)
mysql.connector.errors.DataError: 1292 (22007): Incorrect datetime value: '' for column 'authTime' at row 1

During handling of the above exception, another exception occurred:

Traceback (most recent call last):
  File "/root/green2go/Backend/userDao.py", line 23, in addUser
    mycursor.execute(sql, val)
  File "/usr/local/lib/python3.6/dist-packages/mysql/connector/cursor.py", line 551, in execute
    self._handle_result(self._connection.cmd_query(stmt))
  File "/usr/local/lib/python3.6/dist-packages/mysql/connector/connection.py", line 490, in cmd_query
    result = self._handle_result(self._send_cmd(ServerCmd.QUERY, query))
  File "/usr/local/lib/python3.6/dist-packages/mysql/connector/connection.py", line 395, in _handle_result
    raise errors.get_exception(packet)
mysql.connector.errors.DataError: 1292 (22007): Incorrect datetime value: '' for column 'authTime' at row 1

During handling of the above exception, another exception occurred:

Traceback (most recent call last):
  File "/root/green2go/Backend/userDao.py", line 23, in addUser
    mycursor.execute(sql, val)
  File "/usr/local/lib/python3.6/dist-packages/mysql/connector/cursor.py", line 551, in execute
    self._handle_result(self._connection.cmd_query(stmt))
  File "/usr/local/lib/python3.6/dist-packages/mysql/connector/connection.py", line 490, in cmd_query
    result = self._handle_result(self._send_cmd(ServerCmd.QUERY, query))
  File "/usr/local/lib/python3.6/dist-packages/mysql/connector/connection.py", line 395, in _handle_result
    raise errors.get_exception(packet)
mysql.connector.errors.DataError: 1292 (22007): Incorrect datetime value: '' for column 'authTime' at row 1

During handling of the above exception, another exception occurred:

Traceback (most recent call last):
  File "/root/green2go/Backend/userDao.py", line 23, in addUser
    mycursor.execute(sql, val)
  File "/usr/local/lib/python3.6/dist-packages/mysql/connector/cursor.py", line 551, in execute
    self._handle_result(self._connection.cmd_query(stmt))
  File "/usr/local/lib/python3.6/dist-packages/mysql/connector/connection.py", line 490, in cmd_query
    result = self._handle_result(self._send_cmd(ServerCmd.QUERY, query))
  File "/usr/local/lib/python3.6/dist-packages/mysql/connector/connection.py", line 395, in _handle_result
    raise errors.get_exception(packet)
mysql.connector.errors.DataError: 1292 (22007): Incorrect datetime value: '' for column 'authTime' at row 1

During handling of the above exception, another exception occurred:

Traceback (most recent call last):
  File "/root/green2go/Backend/userDao.py", line 23, in addUser
    mycursor.execute(sql, val)
  File "/usr/local/lib/python3.6/dist-packages/mysql/connector/cursor.py", line 551, in execute
    self._handle_result(self._connection.cmd_query(stmt))
  File "/usr/local/lib/python3.6/dist-packages/mysql/connector/connection.py", line 490, in cmd_query
    result = self._handle_result(self._send_cmd(ServerCmd.QUERY, query))
  File "/usr/local/lib/python3.6/dist-packages/mysql/connector/connection.py", line 395, in _handle_result
    raise errors.get_exception(packet)
mysql.connector.errors.DataError: 1292 (22007): Incorrect datetime value: '' for column 'authTime' at row 1

During handling of the above exception, another exception occurred:

Traceback (most recent call last):
  File "/root/green2go/Backend/userDao.py", line 23, in addUser
    mycursor.execute(sql, val)
  File "/usr/local/lib/python3.6/dist-packages/mysql/connector/cursor.py", line 551, in execute
    self._handle_result(self._connection.cmd_query(stmt))
  File "/usr/local/lib/python3.6/dist-packages/mysql/connector/connection.py", line 490, in cmd_query
    result = self._handle_result(self._send_cmd(ServerCmd.QUERY, query))
  File "/usr/local/lib/python3.6/dist-packages/mysql/connector/connection.py", line 395, in _handle_result
    raise errors.get_exception(packet)
mysql.connector.errors.DataError: 1292 (22007): Incorrect datetime value: '' for column 'authTime' at row 1

During handling of the above exception, another exception occurred:

Traceback (most recent call last):
  File "/root/green2go/Backend/userDao.py", line 23, in addUser
    mycursor.execute(sql, val)
  File "/usr/local/lib/python3.6/dist-packages/mysql/connector/cursor.py", line 551, in execute
    self._handle_result(self._connection.cmd_query(stmt))
  File "/usr/local/lib/python3.6/dist-packages/mysql/connector/connection.py", line 490, in cmd_query
    result = self._handle_result(self._send_cmd(ServerCmd.QUERY, query))
  File "/usr/local/lib/python3.6/dist-packages/mysql/connector/connection.py", line 395, in _handle_result
    raise errors.get_exception(packet)
mysql.connector.errors.DataError: 1292 (22007): Incorrect datetime value: '' for column 'authTime' at row 1

During handling of the above exception, another exception occurred:

Traceback (most recent call last):
  File "/root/green2go/Backend/userDao.py", line 23, in addUser
    mycursor.execute(sql, val)
  File "/usr/local/lib/python3.6/dist-packages/mysql/connector/cursor.py", line 551, in execute
    self._handle_result(self._connection.cmd_query(stmt))
  File "/usr/local/lib/python3.6/dist-packages/mysql/connector/connection.py", line 490, in cmd_query
    result = self._handle_result(self._send_cmd(ServerCmd.QUERY, query))
  File "/usr/local/lib/python3.6/dist-packages/mysql/connector/connection.py", line 395, in _handle_result
    raise errors.get_exception(packet)
mysql.connector.errors.DataError: 1292 (22007): Incorrect datetime value: '' for column 'authTime' at row 1

During handling of the above exception, another exception occurred:

Traceback (most recent call last):
  File "/root/green2go/Backend/userDao.py", line 23, in addUser
    mycursor.execute(sql, val)
  File "/usr/local/lib/python3.6/dist-packages/mysql/connector/cursor.py", line 551, in execute
    self._handle_result(self._connection.cmd_query(stmt))
  File "/usr/local/lib/python3.6/dist-packages/mysql/connector/connection.py", line 490, in cmd_query
    result = self._handle_result(self._send_cmd(ServerCmd.QUERY, query))
  File "/usr/local/lib/python3.6/dist-packages/mysql/connector/connection.py", line 395, in _handle_result
    raise errors.get_exception(packet)
mysql.connector.errors.DataError: 1292 (22007): Incorrect datetime value: '' for column 'authTime' at row 1

During handling of the above exception, another exception occurred:

Traceback (most recent call last):
  File "/root/green2go/Backend/userDao.py", line 23, in addUser
    mycursor.execute(sql, val)
  File "/usr/local/lib/python3.6/dist-packages/mysql/connector/cursor.py", line 551, in execute
    self._handle_result(self._connection.cmd_query(stmt))
  File "/usr/local/lib/python3.6/dist-packages/mysql/connector/connection.py", line 490, in cmd_query
    result = self._handle_result(self._send_cmd(ServerCmd.QUERY, query))
  File "/usr/local/lib/python3.6/dist-packages/mysql/connector/connection.py", line 395, in _handle_result
    raise errors.get_exception(packet)
mysql.connector.errors.DataError: 1292 (22007): Incorrect datetime value: '' for column 'authTime' at row 1

During handling of the above exception, another exception occurred:

Traceback (most recent call last):
  File "/root/green2go/Backend/userDao.py", line 23, in addUser
    mycursor.execute(sql, val)
  File "/usr/local/lib/python3.6/dist-packages/mysql/connector/cursor.py", line 551, in execute
    self._handle_result(self._connection.cmd_query(stmt))
  File "/usr/local/lib/python3.6/dist-packages/mysql/connector/connection.py", line 490, in cmd_query
    result = self._handle_result(self._send_cmd(ServerCmd.QUERY, query))
  File "/usr/local/lib/python3.6/dist-packages/mysql/connector/connection.py", line 395, in _handle_result
    raise errors.get_exception(packet)
mysql.connector.errors.DataError: 1292 (22007): Incorrect datetime value: '' for column 'authTime' at row 1

During handling of the above exception, another exception occurred:

Traceback (most recent call last):
  File "/root/green2go/Backend/userDao.py", line 23, in addUser
    mycursor.execute(sql, val)
  File "/usr/local/lib/python3.6/dist-packages/mysql/connector/cursor.py", line 551, in execute
    self._handle_result(self._connection.cmd_query(stmt))
  File "/usr/local/lib/python3.6/dist-packages/mysql/connector/connection.py", line 490, in cmd_query
    result = self._handle_result(self._send_cmd(ServerCmd.QUERY, query))
  File "/usr/local/lib/python3.6/dist-packages/mysql/connector/connection.py", line 395, in _handle_result
    raise errors.get_exception(packet)
mysql.connector.errors.DataError: 1292 (22007): Incorrect datetime value: '' for column 'authTime' at row 1

During handling of the above exception, another exception occurred:

Traceback (most recent call last):
  File "/root/green2go/Backend/userDao.py", line 23, in addUser
    mycursor.execute(sql, val)
  File "/usr/local/lib/python3.6/dist-packages/mysql/connector/cursor.py", line 551, in execute
    self._handle_result(self._connection.cmd_query(stmt))
  File "/usr/local/lib/python3.6/dist-packages/mysql/connector/connection.py", line 490, in cmd_query
    result = self._handle_result(self._send_cmd(ServerCmd.QUERY, query))
  File "/usr/local/lib/python3.6/dist-packages/mysql/connector/connection.py", line 395, in _handle_result
    raise errors.get_exception(packet)
mysql.connector.errors.DataError: 1292 (22007): Incorrect datetime value: '' for column 'authTime' at row 1

During handling of the above exception, another exception occurred:

Traceback (most recent call last):
  File "/root/green2go/Backend/userDao.py", line 23, in addUser
    mycursor.execute(sql, val)
  File "/usr/local/lib/python3.6/dist-packages/mysql/connector/cursor.py", line 551, in execute
    self._handle_result(self._connection.cmd_query(stmt))
  File "/usr/local/lib/python3.6/dist-packages/mysql/connector/connection.py", line 490, in cmd_query
    result = self._handle_result(self._send_cmd(ServerCmd.QUERY, query))
  File "/usr/local/lib/python3.6/dist-packages/mysql/connector/connection.py", line 395, in _handle_result
    raise errors.get_exception(packet)
mysql.connector.errors.DataError: 1292 (22007): Incorrect datetime value: '' for column 'authTime' at row 1

During handling of the above exception, another exception occurred:

Traceback (most recent call last):
  File "/root/green2go/Backend/userDao.py", line 23, in addUser
    mycursor.execute(sql, val)
  File "/usr/local/lib/python3.6/dist-packages/mysql/connector/cursor.py", line 551, in execute
    self._handle_result(self._connection.cmd_query(stmt))
  File "/usr/local/lib/python3.6/dist-packages/mysql/connector/connection.py", line 490, in cmd_query
    result = self._handle_result(self._send_cmd(ServerCmd.QUERY, query))
  File "/usr/local/lib/python3.6/dist-packages/mysql/connector/connection.py", line 395, in _handle_result
    raise errors.get_exception(packet)
mysql.connector.errors.DataError: 1292 (22007): Incorrect datetime value: '' for column 'authTime' at row 1

During handling of the above exception, another exception occurred:

Traceback (most recent call last):
  File "/root/green2go/Backend/userDao.py", line 23, in addUser
    mycursor.execute(sql, val)
  File "/usr/local/lib/python3.6/dist-packages/mysql/connector/cursor.py", line 551, in execute
    self._handle_result(self._connection.cmd_query(stmt))
  File "/usr/local/lib/python3.6/dist-packages/mysql/connector/connection.py", line 490, in cmd_query
    result = self._handle_result(self._send_cmd(ServerCmd.QUERY, query))
  File "/usr/local/lib/python3.6/dist-packages/mysql/connector/connection.py", line 395, in _handle_result
    raise errors.get_exception(packet)
mysql.connector.errors.DataError: 1292 (22007): Incorrect datetime value: '' for column 'authTime' at row 1

During handling of the above exception, another exception occurred:

Traceback (most recent call last):
  File "/root/green2go/Backend/userDao.py", line 23, in addUser
    mycursor.execute(sql, val)
  File "/usr/local/lib/python3.6/dist-packages/mysql/connector/cursor.py", line 551, in execute
    self._handle_result(self._connection.cmd_query(stmt))
  File "/usr/local/lib/python3.6/dist-packages/mysql/connector/connection.py", line 490, in cmd_query
    result = self._handle_result(self._send_cmd(ServerCmd.QUERY, query))
  File "/usr/local/lib/python3.6/dist-packages/mysql/connector/connection.py", line 395, in _handle_result
    raise errors.get_exception(packet)
mysql.connector.errors.DataError: 1292 (22007): Incorrect datetime value: '' for column 'authTime' at row 1

During handling of the above exception, another exception occurred:

Traceback (most recent call last):
  File "/root/green2go/Backend/userDao.py", line 23, in addUser
    mycursor.execute(sql, val)
  File "/usr/local/lib/python3.6/dist-packages/mysql/connector/cursor.py", line 551, in execute
    self._handle_result(self._connection.cmd_query(stmt))
  File "/usr/local/lib/python3.6/dist-packages/mysql/connector/connection.py", line 490, in cmd_query
    result = self._handle_result(self._send_cmd(ServerCmd.QUERY, query))
  File "/usr/local/lib/python3.6/dist-packages/mysql/connector/connection.py", line 395, in _handle_result
    raise errors.get_exception(packet)
mysql.connector.errors.DataError: 1292 (22007): Incorrect datetime value: '' for column 'authTime' at row 1

During handling of the above exception, another exception occurred:

Traceback (most recent call last):
  File "/root/green2go/Backend/userDao.py", line 23, in addUser
    mycursor.execute(sql, val)
  File "/usr/local/lib/python3.6/dist-packages/mysql/connector/cursor.py", line 551, in execute
    self._handle_result(self._connection.cmd_query(stmt))
  File "/usr/local/lib/python3.6/dist-packages/mysql/connector/connection.py", line 490, in cmd_query
    result = self._handle_result(self._send_cmd(ServerCmd.QUERY, query))
  File "/usr/local/lib/python3.6/dist-packages/mysql/connector/connection.py", line 395, in _handle_result
    raise errors.get_exception(packet)
mysql.connector.errors.DataError: 1292 (22007): Incorrect datetime value: '' for column 'authTime' at row 1

During handling of the above exception, another exception occurred:

Traceback (most recent call last):
  File "/root/green2go/Backend/userDao.py", line 23, in addUser
    mycursor.execute(sql, val)
  File "/usr/local/lib/python3.6/dist-packages/mysql/connector/cursor.py", line 551, in execute
    self._handle_result(self._connection.cmd_query(stmt))
  File "/usr/local/lib/python3.6/dist-packages/mysql/connector/connection.py", line 490, in cmd_query
    result = self._handle_result(self._send_cmd(ServerCmd.QUERY, query))
  File "/usr/local/lib/python3.6/dist-packages/mysql/connector/connection.py", line 395, in _handle_result
    raise errors.get_exception(packet)
mysql.connector.errors.DataError: 1292 (22007): Incorrect datetime value: '' for column 'authTime' at row 1

During handling of the above exception, another exception occurred:

Traceback (most recent call last):
  File "/root/green2go/Backend/userDao.py", line 23, in addUser
    mycursor.execute(sql, val)
  File "/usr/local/lib/python3.6/dist-packages/mysql/connector/cursor.py", line 551, in execute
    self._handle_result(self._connection.cmd_query(stmt))
  File "/usr/local/lib/python3.6/dist-packages/mysql/connector/connection.py", line 490, in cmd_query
    result = self._handle_result(self._send_cmd(ServerCmd.QUERY, query))
  File "/usr/local/lib/python3.6/dist-packages/mysql/connector/connection.py", line 395, in _handle_result
    raise errors.get_exception(packet)
mysql.connector.errors.DataError: 1292 (22007): Incorrect datetime value: '' for column 'authTime' at row 1

During handling of the above exception, another exception occurred:

Traceback (most recent call last):
  File "/root/green2go/Backend/userDao.py", line 23, in addUser
    mycursor.execute(sql, val)
  File "/usr/local/lib/python3.6/dist-packages/mysql/connector/cursor.py", line 551, in execute
    self._handle_result(self._connection.cmd_query(stmt))
  File "/usr/local/lib/python3.6/dist-packages/mysql/connector/connection.py", line 490, in cmd_query
    result = self._handle_result(self._send_cmd(ServerCmd.QUERY, query))
  File "/usr/local/lib/python3.6/dist-packages/mysql/connector/connection.py", line 395, in _handle_result
    raise errors.get_exception(packet)
mysql.connector.errors.DataError: 1292 (22007): Incorrect datetime value: '' for column 'authTime' at row 1

During handling of the above exception, another exception occurred:

Traceback (most recent call last):
  File "/root/green2go/Backend/userDao.py", line 23, in addUser
    mycursor.execute(sql, val)
  File "/usr/local/lib/python3.6/dist-packages/mysql/connector/cursor.py", line 551, in execute
    self._handle_result(self._connection.cmd_query(stmt))
  File "/usr/local/lib/python3.6/dist-packages/mysql/connector/connection.py", line 490, in cmd_query
    result = self._handle_result(self._send_cmd(ServerCmd.QUERY, query))
  File "/usr/local/lib/python3.6/dist-packages/mysql/connector/connection.py", line 395, in _handle_result
    raise errors.get_exception(packet)
mysql.connector.errors.DataError: 1292 (22007): Incorrect datetime value: '' for column 'authTime' at row 1

During handling of the above exception, another exception occurred:

Traceback (most recent call last):
  File "/root/green2go/Backend/userDao.py", line 23, in addUser
    mycursor.execute(sql, val)
  File "/usr/local/lib/python3.6/dist-packages/mysql/connector/cursor.py", line 551, in execute
    self._handle_result(self._connection.cmd_query(stmt))
  File "/usr/local/lib/python3.6/dist-packages/mysql/connector/connection.py", line 490, in cmd_query
    result = self._handle_result(self._send_cmd(ServerCmd.QUERY, query))
  File "/usr/local/lib/python3.6/dist-packages/mysql/connector/connection.py", line 395, in _handle_result
    raise errors.get_exception(packet)
mysql.connector.errors.DataError: 1292 (22007): Incorrect datetime value: '' for column 'authTime' at row 1

During handling of the above exception, another exception occurred:

Traceback (most recent call last):
  File "/root/green2go/Backend/userDao.py", line 23, in addUser
    mycursor.execute(sql, val)
  File "/usr/local/lib/python3.6/dist-packages/mysql/connector/cursor.py", line 551, in execute
    self._handle_result(self._connection.cmd_query(stmt))
  File "/usr/local/lib/python3.6/dist-packages/mysql/connector/connection.py", line 490, in cmd_query
    result = self._handle_result(self._send_cmd(ServerCmd.QUERY, query))
  File "/usr/local/lib/python3.6/dist-packages/mysql/connector/connection.py", line 395, in _handle_result
    raise errors.get_exception(packet)
mysql.connector.errors.DataError: 1292 (22007): Incorrect datetime value: '' for column 'authTime' at row 1

During handling of the above exception, another exception occurred:

Traceback (most recent call last):
  File "/root/green2go/Backend/userDao.py", line 23, in addUser
    mycursor.execute(sql, val)
  File "/usr/local/lib/python3.6/dist-packages/mysql/connector/cursor.py", line 551, in execute
    self._handle_result(self._connection.cmd_query(stmt))
  File "/usr/local/lib/python3.6/dist-packages/mysql/connector/connection.py", line 490, in cmd_query
    result = self._handle_result(self._send_cmd(ServerCmd.QUERY, query))
  File "/usr/local/lib/python3.6/dist-packages/mysql/connector/connection.py", line 395, in _handle_result
    raise errors.get_exception(packet)
mysql.connector.errors.DataError: 1292 (22007): Incorrect datetime value: '' for column 'authTime' at row 1

During handling of the above exception, another exception occurred:

Traceback (most recent call last):
  File "/root/green2go/Backend/userDao.py", line 23, in addUser
    mycursor.execute(sql, val)
  File "/usr/local/lib/python3.6/dist-packages/mysql/connector/cursor.py", line 551, in execute
    self._handle_result(self._connection.cmd_query(stmt))
  File "/usr/local/lib/python3.6/dist-packages/mysql/connector/connection.py", line 490, in cmd_query
    result = self._handle_result(self._send_cmd(ServerCmd.QUERY, query))
  File "/usr/local/lib/python3.6/dist-packages/mysql/connector/connection.py", line 395, in _handle_result
    raise errors.get_exception(packet)
mysql.connector.errors.DataError: 1292 (22007): Incorrect datetime value: '' for column 'authTime' at row 1

During handling of the above exception, another exception occurred:

Traceback (most recent call last):
  File "/root/green2go/Backend/userDao.py", line 23, in addUser
    mycursor.execute(sql, val)
  File "/usr/local/lib/python3.6/dist-packages/mysql/connector/cursor.py", line 551, in execute
    self._handle_result(self._connection.cmd_query(stmt))
  File "/usr/local/lib/python3.6/dist-packages/mysql/connector/connection.py", line 490, in cmd_query
    result = self._handle_result(self._send_cmd(ServerCmd.QUERY, query))
  File "/usr/local/lib/python3.6/dist-packages/mysql/connector/connection.py", line 395, in _handle_result
    raise errors.get_exception(packet)
mysql.connector.errors.DataError: 1292 (22007): Incorrect datetime value: '' for column 'authTime' at row 1

During handling of the above exception, another exception occurred:

Traceback (most recent call last):
  File "/root/green2go/Backend/userDao.py", line 23, in addUser
    mycursor.execute(sql, val)
  File "/usr/local/lib/python3.6/dist-packages/mysql/connector/cursor.py", line 551, in execute
    self._handle_result(self._connection.cmd_query(stmt))
  File "/usr/local/lib/python3.6/dist-packages/mysql/connector/connection.py", line 490, in cmd_query
    result = self._handle_result(self._send_cmd(ServerCmd.QUERY, query))
  File "/usr/local/lib/python3.6/dist-packages/mysql/connector/connection.py", line 395, in _handle_result
    raise errors.get_exception(packet)
mysql.connector.errors.DataError: 1292 (22007): Incorrect datetime value: '' for column 'authTime' at row 1

During handling of the above exception, another exception occurred:

Traceback (most recent call last):
  File "/root/green2go/Backend/userDao.py", line 23, in addUser
    mycursor.execute(sql, val)
  File "/usr/local/lib/python3.6/dist-packages/mysql/connector/cursor.py", line 551, in execute
    self._handle_result(self._connection.cmd_query(stmt))
  File "/usr/local/lib/python3.6/dist-packages/mysql/connector/connection.py", line 490, in cmd_query
    result = self._handle_result(self._send_cmd(ServerCmd.QUERY, query))
  File "/usr/local/lib/python3.6/dist-packages/mysql/connector/connection.py", line 395, in _handle_result
    raise errors.get_exception(packet)
mysql.connector.errors.DataError: 1292 (22007): Incorrect datetime value: '' for column 'authTime' at row 1

During handling of the above exception, another exception occurred:

Traceback (most recent call last):
  File "/root/green2go/Backend/userDao.py", line 23, in addUser
    mycursor.execute(sql, val)
  File "/usr/local/lib/python3.6/dist-packages/mysql/connector/cursor.py", line 551, in execute
    self._handle_result(self._connection.cmd_query(stmt))
  File "/usr/local/lib/python3.6/dist-packages/mysql/connector/connection.py", line 490, in cmd_query
    result = self._handle_result(self._send_cmd(ServerCmd.QUERY, query))
  File "/usr/local/lib/python3.6/dist-packages/mysql/connector/connection.py", line 395, in _handle_result
    raise errors.get_exception(packet)
mysql.connector.errors.DataError: 1292 (22007): Incorrect datetime value: '' for column 'authTime' at row 1

During handling of the above exception, another exception occurred:

Traceback (most recent call last):
  File "/root/green2go/Backend/userDao.py", line 23, in addUser
    mycursor.execute(sql, val)
  File "/usr/local/lib/python3.6/dist-packages/mysql/connector/cursor.py", line 551, in execute
    self._handle_result(self._connection.cmd_query(stmt))
  File "/usr/local/lib/python3.6/dist-packages/mysql/connector/connection.py", line 490, in cmd_query
    result = self._handle_result(self._send_cmd(ServerCmd.QUERY, query))
  File "/usr/local/lib/python3.6/dist-packages/mysql/connector/connection.py", line 395, in _handle_result
    raise errors.get_exception(packet)
mysql.connector.errors.DataError: 1292 (22007): Incorrect datetime value: '' for column 'authTime' at row 1

During handling of the above exception, another exception occurred:

Traceback (most recent call last):
  File "/root/green2go/Backend/userDao.py", line 23, in addUser
    mycursor.execute(sql, val)
  File "/usr/local/lib/python3.6/dist-packages/mysql/connector/cursor.py", line 551, in execute
    self._handle_result(self._connection.cmd_query(stmt))
  File "/usr/local/lib/python3.6/dist-packages/mysql/connector/connection.py", line 490, in cmd_query
    result = self._handle_result(self._send_cmd(ServerCmd.QUERY, query))
  File "/usr/local/lib/python3.6/dist-packages/mysql/connector/connection.py", line 395, in _handle_result
    raise errors.get_exception(packet)
mysql.connector.errors.DataError: 1292 (22007): Incorrect datetime value: '' for column 'authTime' at row 1

During handling of the above exception, another exception occurred:

Traceback (most recent call last):
  File "/root/green2go/Backend/userDao.py", line 23, in addUser
    mycursor.execute(sql, val)
  File "/usr/local/lib/python3.6/dist-packages/mysql/connector/cursor.py", line 551, in execute
    self._handle_result(self._connection.cmd_query(stmt))
  File "/usr/local/lib/python3.6/dist-packages/mysql/connector/connection.py", line 490, in cmd_query
    result = self._handle_result(self._send_cmd(ServerCmd.QUERY, query))
  File "/usr/local/lib/python3.6/dist-packages/mysql/connector/connection.py", line 395, in _handle_result
    raise errors.get_exception(packet)
mysql.connector.errors.DataError: 1292 (22007): Incorrect datetime value: '' for column 'authTime' at row 1

During handling of the above exception, another exception occurred:

Traceback (most recent call last):
  File "/root/green2go/Backend/userDao.py", line 23, in addUser
    mycursor.execute(sql, val)
  File "/usr/local/lib/python3.6/dist-packages/mysql/connector/cursor.py", line 551, in execute
    self._handle_result(self._connection.cmd_query(stmt))
  File "/usr/local/lib/python3.6/dist-packages/mysql/connector/connection.py", line 490, in cmd_query
    result = self._handle_result(self._send_cmd(ServerCmd.QUERY, query))
  File "/usr/local/lib/python3.6/dist-packages/mysql/connector/connection.py", line 395, in _handle_result
    raise errors.get_exception(packet)
mysql.connector.errors.DataError: 1292 (22007): Incorrect datetime value: '' for column 'authTime' at row 1

During handling of the above exception, another exception occurred:

Traceback (most recent call last):
  File "/root/green2go/Backend/userDao.py", line 23, in addUser
    mycursor.execute(sql, val)
  File "/usr/local/lib/python3.6/dist-packages/mysql/connector/cursor.py", line 551, in execute
    self._handle_result(self._connection.cmd_query(stmt))
  File "/usr/local/lib/python3.6/dist-packages/mysql/connector/connection.py", line 490, in cmd_query
    result = self._handle_result(self._send_cmd(ServerCmd.QUERY, query))
  File "/usr/local/lib/python3.6/dist-packages/mysql/connector/connection.py", line 395, in _handle_result
    raise errors.get_exception(packet)
mysql.connector.errors.DataError: 1292 (22007): Incorrect datetime value: '' for column 'authTime' at row 1

During handling of the above exception, another exception occurred:

Traceback (most recent call last):
  File "/root/green2go/Backend/userDao.py", line 23, in addUser
    mycursor.execute(sql, val)
  File "/usr/local/lib/python3.6/dist-packages/mysql/connector/cursor.py", line 551, in execute
    self._handle_result(self._connection.cmd_query(stmt))
  File "/usr/local/lib/python3.6/dist-packages/mysql/connector/connection.py", line 490, in cmd_query
    result = self._handle_result(self._send_cmd(ServerCmd.QUERY, query))
  File "/usr/local/lib/python3.6/dist-packages/mysql/connector/connection.py", line 395, in _handle_result
    raise errors.get_exception(packet)
mysql.connector.errors.DataError: 1292 (22007): Incorrect datetime value: '' for column 'authTime' at row 1

During handling of the above exception, another exception occurred:

Traceback (most recent call last):
  File "/root/green2go/Backend/userDao.py", line 23, in addUser
    mycursor.execute(sql, val)
  File "/usr/local/lib/python3.6/dist-packages/mysql/connector/cursor.py", line 551, in execute
    self._handle_result(self._connection.cmd_query(stmt))
  File "/usr/local/lib/python3.6/dist-packages/mysql/connector/connection.py", line 490, in cmd_query
    result = self._handle_result(self._send_cmd(ServerCmd.QUERY, query))
  File "/usr/local/lib/python3.6/dist-packages/mysql/connector/connection.py", line 395, in _handle_result
    raise errors.get_exception(packet)
mysql.connector.errors.DataError: 1292 (22007): Incorrect datetime value: '' for column 'authTime' at row 1

During handling of the above exception, another exception occurred:

Traceback (most recent call last):
  File "/root/green2go/Backend/userDao.py", line 23, in addUser
    mycursor.execute(sql, val)
  File "/usr/local/lib/python3.6/dist-packages/mysql/connector/cursor.py", line 551, in execute
    self._handle_result(self._connection.cmd_query(stmt))
  File "/usr/local/lib/python3.6/dist-packages/mysql/connector/connection.py", line 490, in cmd_query
    result = self._handle_result(self._send_cmd(ServerCmd.QUERY, query))
  File "/usr/local/lib/python3.6/dist-packages/mysql/connector/connection.py", line 395, in _handle_result
    raise errors.get_exception(packet)
mysql.connector.errors.DataError: 1292 (22007): Incorrect datetime value: '' for column 'authTime' at row 1

During handling of the above exception, another exception occurred:

Traceback (most recent call last):
  File "/root/green2go/Backend/userDao.py", line 23, in addUser
    mycursor.execute(sql, val)
  File "/usr/local/lib/python3.6/dist-packages/mysql/connector/cursor.py", line 551, in execute
    self._handle_result(self._connection.cmd_query(stmt))
  File "/usr/local/lib/python3.6/dist-packages/mysql/connector/connection.py", line 490, in cmd_query
    result = self._handle_result(self._send_cmd(ServerCmd.QUERY, query))
  File "/usr/local/lib/python3.6/dist-packages/mysql/connector/connection.py", line 395, in _handle_result
    raise errors.get_exception(packet)
mysql.connector.errors.DataError: 1292 (22007): Incorrect datetime value: '' for column 'authTime' at row 1

During handling of the above exception, another exception occurred:

Traceback (most recent call last):
  File "/root/green2go/Backend/userDao.py", line 23, in addUser
    mycursor.execute(sql, val)
  File "/usr/local/lib/python3.6/dist-packages/mysql/connector/cursor.py", line 551, in execute
    self._handle_result(self._connection.cmd_query(stmt))
  File "/usr/local/lib/python3.6/dist-packages/mysql/connector/connection.py", line 490, in cmd_query
    result = self._handle_result(self._send_cmd(ServerCmd.QUERY, query))
  File "/usr/local/lib/python3.6/dist-packages/mysql/connector/connection.py", line 395, in _handle_result
    raise errors.get_exception(packet)
mysql.connector.errors.DataError: 1292 (22007): Incorrect datetime value: '' for column 'authTime' at row 1

During handling of the above exception, another exception occurred:

Traceback (most recent call last):
  File "/root/green2go/Backend/userDao.py", line 23, in addUser
    mycursor.execute(sql, val)
  File "/usr/local/lib/python3.6/dist-packages/mysql/connector/cursor.py", line 551, in execute
    self._handle_result(self._connection.cmd_query(stmt))
  File "/usr/local/lib/python3.6/dist-packages/mysql/connector/connection.py", line 490, in cmd_query
    result = self._handle_result(self._send_cmd(ServerCmd.QUERY, query))
  File "/usr/local/lib/python3.6/dist-packages/mysql/connector/connection.py", line 395, in _handle_result
    raise errors.get_exception(packet)
mysql.connector.errors.DataError: 1292 (22007): Incorrect datetime value: '' for column 'authTime' at row 1

During handling of the above exception, another exception occurred:

Traceback (most recent call last):
  File "/root/green2go/Backend/userDao.py", line 23, in addUser
    mycursor.execute(sql, val)
  File "/usr/local/lib/python3.6/dist-packages/mysql/connector/cursor.py", line 551, in execute
    self._handle_result(self._connection.cmd_query(stmt))
  File "/usr/local/lib/python3.6/dist-packages/mysql/connector/connection.py", line 490, in cmd_query
    result = self._handle_result(self._send_cmd(ServerCmd.QUERY, query))
  File "/usr/local/lib/python3.6/dist-packages/mysql/connector/connection.py", line 395, in _handle_result
    raise errors.get_exception(packet)
mysql.connector.errors.DataError: 1292 (22007): Incorrect datetime value: '' for column 'authTime' at row 1

During handling of the above exception, another exception occurred:

Traceback (most recent call last):
  File "/root/green2go/Backend/userDao.py", line 23, in addUser
    mycursor.execute(sql, val)
  File "/usr/local/lib/python3.6/dist-packages/mysql/connector/cursor.py", line 551, in execute
    self._handle_result(self._connection.cmd_query(stmt))
  File "/usr/local/lib/python3.6/dist-packages/mysql/connector/connection.py", line 490, in cmd_query
    result = self._handle_result(self._send_cmd(ServerCmd.QUERY, query))
  File "/usr/local/lib/python3.6/dist-packages/mysql/connector/connection.py", line 395, in _handle_result
    raise errors.get_exception(packet)
mysql.connector.errors.DataError: 1292 (22007): Incorrect datetime value: '' for column 'authTime' at row 1

During handling of the above exception, another exception occurred:

Traceback (most recent call last):
  File "/root/green2go/Backend/userDao.py", line 23, in addUser
    mycursor.execute(sql, val)
  File "/usr/local/lib/python3.6/dist-packages/mysql/connector/cursor.py", line 551, in execute
    self._handle_result(self._connection.cmd_query(stmt))
  File "/usr/local/lib/python3.6/dist-packages/mysql/connector/connection.py", line 490, in cmd_query
    result = self._handle_result(self._send_cmd(ServerCmd.QUERY, query))
  File "/usr/local/lib/python3.6/dist-packages/mysql/connector/connection.py", line 395, in _handle_result
    raise errors.get_exception(packet)
mysql.connector.errors.DataError: 1292 (22007): Incorrect datetime value: '' for column 'authTime' at row 1

During handling of the above exception, another exception occurred:

Traceback (most recent call last):
  File "/root/green2go/Backend/userDao.py", line 23, in addUser
    mycursor.execute(sql, val)
  File "/usr/local/lib/python3.6/dist-packages/mysql/connector/cursor.py", line 551, in execute
    self._handle_result(self._connection.cmd_query(stmt))
  File "/usr/local/lib/python3.6/dist-packages/mysql/connector/connection.py", line 490, in cmd_query
    result = self._handle_result(self._send_cmd(ServerCmd.QUERY, query))
  File "/usr/local/lib/python3.6/dist-packages/mysql/connector/connection.py", line 395, in _handle_result
    raise errors.get_exception(packet)
mysql.connector.errors.DataError: 1292 (22007): Incorrect datetime value: '' for column 'authTime' at row 1

During handling of the above exception, another exception occurred:

Traceback (most recent call last):
  File "/root/green2go/Backend/userDao.py", line 23, in addUser
    mycursor.execute(sql, val)
  File "/usr/local/lib/python3.6/dist-packages/mysql/connector/cursor.py", line 551, in execute
    self._handle_result(self._connection.cmd_query(stmt))
  File "/usr/local/lib/python3.6/dist-packages/mysql/connector/connection.py", line 490, in cmd_query
    result = self._handle_result(self._send_cmd(ServerCmd.QUERY, query))
  File "/usr/local/lib/python3.6/dist-packages/mysql/connector/connection.py", line 395, in _handle_result
    raise errors.get_exception(packet)
mysql.connector.errors.DataError: 1292 (22007): Incorrect datetime value: '' for column 'authTime' at row 1

During handling of the above exception, another exception occurred:

Traceback (most recent call last):
  File "/root/green2go/Backend/userDao.py", line 23, in addUser
    mycursor.execute(sql, val)
  File "/usr/local/lib/python3.6/dist-packages/mysql/connector/cursor.py", line 551, in execute
    self._handle_result(self._connection.cmd_query(stmt))
  File "/usr/local/lib/python3.6/dist-packages/mysql/connector/connection.py", line 490, in cmd_query
    result = self._handle_result(self._send_cmd(ServerCmd.QUERY, query))
  File "/usr/local/lib/python3.6/dist-packages/mysql/connector/connection.py", line 395, in _handle_result
    raise errors.get_exception(packet)
mysql.connector.errors.DataError: 1292 (22007): Incorrect datetime value: '' for column 'authTime' at row 1

During handling of the above exception, another exception occurred:

Traceback (most recent call last):
  File "/root/green2go/Backend/userDao.py", line 23, in addUser
    mycursor.execute(sql, val)
  File "/usr/local/lib/python3.6/dist-packages/mysql/connector/cursor.py", line 551, in execute
    self._handle_result(self._connection.cmd_query(stmt))
  File "/usr/local/lib/python3.6/dist-packages/mysql/connector/connection.py", line 490, in cmd_query
    result = self._handle_result(self._send_cmd(ServerCmd.QUERY, query))
  File "/usr/local/lib/python3.6/dist-packages/mysql/connector/connection.py", line 395, in _handle_result
    raise errors.get_exception(packet)
mysql.connector.errors.DataError: 1292 (22007): Incorrect datetime value: '' for column 'authTime' at row 1

During handling of the above exception, another exception occurred:

Traceback (most recent call last):
  File "/root/green2go/Backend/userDao.py", line 23, in addUser
    mycursor.execute(sql, val)
  File "/usr/local/lib/python3.6/dist-packages/mysql/connector/cursor.py", line 551, in execute
    self._handle_result(self._connection.cmd_query(stmt))
  File "/usr/local/lib/python3.6/dist-packages/mysql/connector/connection.py", line 490, in cmd_query
    result = self._handle_result(self._send_cmd(ServerCmd.QUERY, query))
  File "/usr/local/lib/python3.6/dist-packages/mysql/connector/connection.py", line 395, in _handle_result
    raise errors.get_exception(packet)
mysql.connector.errors.DataError: 1292 (22007): Incorrect datetime value: '' for column 'authTime' at row 1

During handling of the above exception, another exception occurred:

Traceback (most recent call last):
  File "/root/green2go/Backend/userDao.py", line 23, in addUser
    mycursor.execute(sql, val)
  File "/usr/local/lib/python3.6/dist-packages/mysql/connector/cursor.py", line 551, in execute
    self._handle_result(self._connection.cmd_query(stmt))
  File "/usr/local/lib/python3.6/dist-packages/mysql/connector/connection.py", line 490, in cmd_query
    result = self._handle_result(self._send_cmd(ServerCmd.QUERY, query))
  File "/usr/local/lib/python3.6/dist-packages/mysql/connector/connection.py", line 395, in _handle_result
    raise errors.get_exception(packet)
mysql.connector.errors.DataError: 1292 (22007): Incorrect datetime value: '' for column 'authTime' at row 1

During handling of the above exception, another exception occurred:

Traceback (most recent call last):
  File "/root/green2go/Backend/userDao.py", line 23, in addUser
    mycursor.execute(sql, val)
  File "/usr/local/lib/python3.6/dist-packages/mysql/connector/cursor.py", line 551, in execute
    self._handle_result(self._connection.cmd_query(stmt))
  File "/usr/local/lib/python3.6/dist-packages/mysql/connector/connection.py", line 490, in cmd_query
    result = self._handle_result(self._send_cmd(ServerCmd.QUERY, query))
  File "/usr/local/lib/python3.6/dist-packages/mysql/connector/connection.py", line 395, in _handle_result
    raise errors.get_exception(packet)
mysql.connector.errors.DataError: 1292 (22007): Incorrect datetime value: '' for column 'authTime' at row 1

During handling of the above exception, another exception occurred:

Traceback (most recent call last):
  File "/root/green2go/Backend/userDao.py", line 23, in addUser
    mycursor.execute(sql, val)
  File "/usr/local/lib/python3.6/dist-packages/mysql/connector/cursor.py", line 551, in execute
    self._handle_result(self._connection.cmd_query(stmt))
  File "/usr/local/lib/python3.6/dist-packages/mysql/connector/connection.py", line 490, in cmd_query
    result = self._handle_result(self._send_cmd(ServerCmd.QUERY, query))
  File "/usr/local/lib/python3.6/dist-packages/mysql/connector/connection.py", line 395, in _handle_result
    raise errors.get_exception(packet)
mysql.connector.errors.DataError: 1292 (22007): Incorrect datetime value: '' for column 'authTime' at row 1

During handling of the above exception, another exception occurred:

Traceback (most recent call last):
  File "/root/green2go/Backend/userDao.py", line 23, in addUser
    mycursor.execute(sql, val)
  File "/usr/local/lib/python3.6/dist-packages/mysql/connector/cursor.py", line 551, in execute
    self._handle_result(self._connection.cmd_query(stmt))
  File "/usr/local/lib/python3.6/dist-packages/mysql/connector/connection.py", line 490, in cmd_query
    result = self._handle_result(self._send_cmd(ServerCmd.QUERY, query))
  File "/usr/local/lib/python3.6/dist-packages/mysql/connector/connection.py", line 395, in _handle_result
    raise errors.get_exception(packet)
mysql.connector.errors.DataError: 1292 (22007): Incorrect datetime value: '' for column 'authTime' at row 1

During handling of the above exception, another exception occurred:

Traceback (most recent call last):
  File "/root/green2go/Backend/userDao.py", line 23, in addUser
    mycursor.execute(sql, val)
  File "/usr/local/lib/python3.6/dist-packages/mysql/connector/cursor.py", line 551, in execute
    self._handle_result(self._connection.cmd_query(stmt))
  File "/usr/local/lib/python3.6/dist-packages/mysql/connector/connection.py", line 490, in cmd_query
    result = self._handle_result(self._send_cmd(ServerCmd.QUERY, query))
  File "/usr/local/lib/python3.6/dist-packages/mysql/connector/connection.py", line 395, in _handle_result
    raise errors.get_exception(packet)
mysql.connector.errors.DataError: 1292 (22007): Incorrect datetime value: '' for column 'authTime' at row 1

During handling of the above exception, another exception occurred:

Traceback (most recent call last):
  File "/root/green2go/Backend/userDao.py", line 23, in addUser
    mycursor.execute(sql, val)
  File "/usr/local/lib/python3.6/dist-packages/mysql/connector/cursor.py", line 551, in execute
    self._handle_result(self._connection.cmd_query(stmt))
  File "/usr/local/lib/python3.6/dist-packages/mysql/connector/connection.py", line 490, in cmd_query
    result = self._handle_result(self._send_cmd(ServerCmd.QUERY, query))
  File "/usr/local/lib/python3.6/dist-packages/mysql/connector/connection.py", line 395, in _handle_result
    raise errors.get_exception(packet)
mysql.connector.errors.DataError: 1292 (22007): Incorrect datetime value: '' for column 'authTime' at row 1

During handling of the above exception, another exception occurred:

Traceback (most recent call last):
  File "/root/green2go/Backend/userDao.py", line 23, in addUser
    mycursor.execute(sql, val)
  File "/usr/local/lib/python3.6/dist-packages/mysql/connector/cursor.py", line 551, in execute
    self._handle_result(self._connection.cmd_query(stmt))
  File "/usr/local/lib/python3.6/dist-packages/mysql/connector/connection.py", line 490, in cmd_query
    result = self._handle_result(self._send_cmd(ServerCmd.QUERY, query))
  File "/usr/local/lib/python3.6/dist-packages/mysql/connector/connection.py", line 395, in _handle_result
    raise errors.get_exception(packet)
mysql.connector.errors.DataError: 1292 (22007): Incorrect datetime value: '' for column 'authTime' at row 1

During handling of the above exception, another exception occurred:

Traceback (most recent call last):
  File "/root/green2go/Backend/userDao.py", line 23, in addUser
    mycursor.execute(sql, val)
  File "/usr/local/lib/python3.6/dist-packages/mysql/connector/cursor.py", line 551, in execute
    self._handle_result(self._connection.cmd_query(stmt))
  File "/usr/local/lib/python3.6/dist-packages/mysql/connector/connection.py", line 490, in cmd_query
    result = self._handle_result(self._send_cmd(ServerCmd.QUERY, query))
  File "/usr/local/lib/python3.6/dist-packages/mysql/connector/connection.py", line 395, in _handle_result
    raise errors.get_exception(packet)
mysql.connector.errors.DataError: 1292 (22007): Incorrect datetime value: '' for column 'authTime' at row 1

During handling of the above exception, another exception occurred:

Traceback (most recent call last):
  File "/root/green2go/Backend/userDao.py", line 23, in addUser
    mycursor.execute(sql, val)
  File "/usr/local/lib/python3.6/dist-packages/mysql/connector/cursor.py", line 551, in execute
    self._handle_result(self._connection.cmd_query(stmt))
  File "/usr/local/lib/python3.6/dist-packages/mysql/connector/connection.py", line 490, in cmd_query
    result = self._handle_result(self._send_cmd(ServerCmd.QUERY, query))
  File "/usr/local/lib/python3.6/dist-packages/mysql/connector/connection.py", line 395, in _handle_result
    raise errors.get_exception(packet)
mysql.connector.errors.DataError: 1292 (22007): Incorrect datetime value: '' for column 'authTime' at row 1

During handling of the above exception, another exception occurred:

Traceback (most recent call last):
  File "/root/green2go/Backend/userDao.py", line 23, in addUser
    mycursor.execute(sql, val)
  File "/usr/local/lib/python3.6/dist-packages/mysql/connector/cursor.py", line 551, in execute
    self._handle_result(self._connection.cmd_query(stmt))
  File "/usr/local/lib/python3.6/dist-packages/mysql/connector/connection.py", line 490, in cmd_query
    result = self._handle_result(self._send_cmd(ServerCmd.QUERY, query))
  File "/usr/local/lib/python3.6/dist-packages/mysql/connector/connection.py", line 395, in _handle_result
    raise errors.get_exception(packet)
mysql.connector.errors.DataError: 1292 (22007): Incorrect datetime value: '' for column 'authTime' at row 1

During handling of the above exception, another exception occurred:

Traceback (most recent call last):
  File "/root/green2go/Backend/userDao.py", line 23, in addUser
    mycursor.execute(sql, val)
  File "/usr/local/lib/python3.6/dist-packages/mysql/connector/cursor.py", line 551, in execute
    self._handle_result(self._connection.cmd_query(stmt))
  File "/usr/local/lib/python3.6/dist-packages/mysql/connector/connection.py", line 490, in cmd_query
    result = self._handle_result(self._send_cmd(ServerCmd.QUERY, query))
  File "/usr/local/lib/python3.6/dist-packages/mysql/connector/connection.py", line 395, in _handle_result
    raise errors.get_exception(packet)
mysql.connector.errors.DataError: 1292 (22007): Incorrect datetime value: '' for column 'authTime' at row 1

During handling of the above exception, another exception occurred:

Traceback (most recent call last):
  File "/root/green2go/Backend/userDao.py", line 23, in addUser
    mycursor.execute(sql, val)
  File "/usr/local/lib/python3.6/dist-packages/mysql/connector/cursor.py", line 551, in execute
    self._handle_result(self._connection.cmd_query(stmt))
  File "/usr/local/lib/python3.6/dist-packages/mysql/connector/connection.py", line 490, in cmd_query
    result = self._handle_result(self._send_cmd(ServerCmd.QUERY, query))
  File "/usr/local/lib/python3.6/dist-packages/mysql/connector/connection.py", line 395, in _handle_result
    raise errors.get_exception(packet)
mysql.connector.errors.DataError: 1292 (22007): Incorrect datetime value: '' for column 'authTime' at row 1

During handling of the above exception, another exception occurred:

Traceback (most recent call last):
  File "/root/green2go/Backend/userDao.py", line 23, in addUser
    mycursor.execute(sql, val)
  File "/usr/local/lib/python3.6/dist-packages/mysql/connector/cursor.py", line 551, in execute
    self._handle_result(self._connection.cmd_query(stmt))
  File "/usr/local/lib/python3.6/dist-packages/mysql/connector/connection.py", line 490, in cmd_query
    result = self._handle_result(self._send_cmd(ServerCmd.QUERY, query))
  File "/usr/local/lib/python3.6/dist-packages/mysql/connector/connection.py", line 395, in _handle_result
    raise errors.get_exception(packet)
mysql.connector.errors.DataError: 1292 (22007): Incorrect datetime value: '' for column 'authTime' at row 1

During handling of the above exception, another exception occurred:

Traceback (most recent call last):
  File "/root/green2go/Backend/userDao.py", line 23, in addUser
    mycursor.execute(sql, val)
  File "/usr/local/lib/python3.6/dist-packages/mysql/connector/cursor.py", line 551, in execute
    self._handle_result(self._connection.cmd_query(stmt))
  File "/usr/local/lib/python3.6/dist-packages/mysql/connector/connection.py", line 490, in cmd_query
    result = self._handle_result(self._send_cmd(ServerCmd.QUERY, query))
  File "/usr/local/lib/python3.6/dist-packages/mysql/connector/connection.py", line 395, in _handle_result
    raise errors.get_exception(packet)
mysql.connector.errors.DataError: 1292 (22007): Incorrect datetime value: '' for column 'authTime' at row 1

During handling of the above exception, another exception occurred:

Traceback (most recent call last):
  File "/root/green2go/Backend/userDao.py", line 23, in addUser
    mycursor.execute(sql, val)
  File "/usr/local/lib/python3.6/dist-packages/mysql/connector/cursor.py", line 551, in execute
    self._handle_result(self._connection.cmd_query(stmt))
  File "/usr/local/lib/python3.6/dist-packages/mysql/connector/connection.py", line 490, in cmd_query
    result = self._handle_result(self._send_cmd(ServerCmd.QUERY, query))
  File "/usr/local/lib/python3.6/dist-packages/mysql/connector/connection.py", line 395, in _handle_result
    raise errors.get_exception(packet)
mysql.connector.errors.DataError: 1292 (22007): Incorrect datetime value: '' for column 'authTime' at row 1

During handling of the above exception, another exception occurred:

Traceback (most recent call last):
  File "/root/green2go/Backend/userDao.py", line 23, in addUser
    mycursor.execute(sql, val)
  File "/usr/local/lib/python3.6/dist-packages/mysql/connector/cursor.py", line 551, in execute
    self._handle_result(self._connection.cmd_query(stmt))
  File "/usr/local/lib/python3.6/dist-packages/mysql/connector/connection.py", line 490, in cmd_query
    result = self._handle_result(self._send_cmd(ServerCmd.QUERY, query))
  File "/usr/local/lib/python3.6/dist-packages/mysql/connector/connection.py", line 395, in _handle_result
    raise errors.get_exception(packet)
mysql.connector.errors.DataError: 1292 (22007): Incorrect datetime value: '' for column 'authTime' at row 1

During handling of the above exception, another exception occurred:

Traceback (most recent call last):
  File "/root/green2go/Backend/userDao.py", line 23, in addUser
    mycursor.execute(sql, val)
  File "/usr/local/lib/python3.6/dist-packages/mysql/connector/cursor.py", line 551, in execute
    self._handle_result(self._connection.cmd_query(stmt))
  File "/usr/local/lib/python3.6/dist-packages/mysql/connector/connection.py", line 490, in cmd_query
    result = self._handle_result(self._send_cmd(ServerCmd.QUERY, query))
  File "/usr/local/lib/python3.6/dist-packages/mysql/connector/connection.py", line 395, in _handle_result
    raise errors.get_exception(packet)
mysql.connector.errors.DataError: 1292 (22007): Incorrect datetime value: '' for column 'authTime' at row 1

During handling of the above exception, another exception occurred:

Traceback (most recent call last):
  File "/root/green2go/Backend/userDao.py", line 23, in addUser
    mycursor.execute(sql, val)
  File "/usr/local/lib/python3.6/dist-packages/mysql/connector/cursor.py", line 551, in execute
    self._handle_result(self._connection.cmd_query(stmt))
  File "/usr/local/lib/python3.6/dist-packages/mysql/connector/connection.py", line 490, in cmd_query
    result = self._handle_result(self._send_cmd(ServerCmd.QUERY, query))
  File "/usr/local/lib/python3.6/dist-packages/mysql/connector/connection.py", line 395, in _handle_result
    raise errors.get_exception(packet)
mysql.connector.errors.DataError: 1292 (22007): Incorrect datetime value: '' for column 'authTime' at row 1

During handling of the above exception, another exception occurred:

Traceback (most recent call last):
  File "/root/green2go/Backend/userDao.py", line 23, in addUser
    mycursor.execute(sql, val)
  File "/usr/local/lib/python3.6/dist-packages/mysql/connector/cursor.py", line 551, in execute
    self._handle_result(self._connection.cmd_query(stmt))
  File "/usr/local/lib/python3.6/dist-packages/mysql/connector/connection.py", line 490, in cmd_query
    result = self._handle_result(self._send_cmd(ServerCmd.QUERY, query))
  File "/usr/local/lib/python3.6/dist-packages/mysql/connector/connection.py", line 395, in _handle_result
    raise errors.get_exception(packet)
mysql.connector.errors.DataError: 1292 (22007): Incorrect datetime value: '' for column 'authTime' at row 1

During handling of the above exception, another exception occurred:

Traceback (most recent call last):
  File "/root/green2go/Backend/userDao.py", line 23, in addUser
    mycursor.execute(sql, val)
  File "/usr/local/lib/python3.6/dist-packages/mysql/connector/cursor.py", line 551, in execute
    self._handle_result(self._connection.cmd_query(stmt))
  File "/usr/local/lib/python3.6/dist-packages/mysql/connector/connection.py", line 490, in cmd_query
    result = self._handle_result(self._send_cmd(ServerCmd.QUERY, query))
  File "/usr/local/lib/python3.6/dist-packages/mysql/connector/connection.py", line 395, in _handle_result
    raise errors.get_exception(packet)
mysql.connector.errors.DataError: 1292 (22007): Incorrect datetime value: '' for column 'authTime' at row 1

During handling of the above exception, another exception occurred:

Traceback (most recent call last):
  File "/root/green2go/Backend/userDao.py", line 23, in addUser
    mycursor.execute(sql, val)
  File "/usr/local/lib/python3.6/dist-packages/mysql/connector/cursor.py", line 551, in execute
    self._handle_result(self._connection.cmd_query(stmt))
  File "/usr/local/lib/python3.6/dist-packages/mysql/connector/connection.py", line 490, in cmd_query
    result = self._handle_result(self._send_cmd(ServerCmd.QUERY, query))
  File "/usr/local/lib/python3.6/dist-packages/mysql/connector/connection.py", line 395, in _handle_result
    raise errors.get_exception(packet)
mysql.connector.errors.DataError: 1292 (22007): Incorrect datetime value: '' for column 'authTime' at row 1

During handling of the above exception, another exception occurred:

Traceback (most recent call last):
  File "/root/green2go/Backend/userDao.py", line 23, in addUser
    mycursor.execute(sql, val)
  File "/usr/local/lib/python3.6/dist-packages/mysql/connector/cursor.py", line 551, in execute
    self._handle_result(self._connection.cmd_query(stmt))
  File "/usr/local/lib/python3.6/dist-packages/mysql/connector/connection.py", line 490, in cmd_query
    result = self._handle_result(self._send_cmd(ServerCmd.QUERY, query))
  File "/usr/local/lib/python3.6/dist-packages/mysql/connector/connection.py", line 395, in _handle_result
    raise errors.get_exception(packet)
mysql.connector.errors.DataError: 1292 (22007): Incorrect datetime value: '' for column 'authTime' at row 1

During handling of the above exception, another exception occurred:

Traceback (most recent call last):
  File "/root/green2go/Backend/userDao.py", line 23, in addUser
    mycursor.execute(sql, val)
  File "/usr/local/lib/python3.6/dist-packages/mysql/connector/cursor.py", line 551, in execute
    self._handle_result(self._connection.cmd_query(stmt))
  File "/usr/local/lib/python3.6/dist-packages/mysql/connector/connection.py", line 490, in cmd_query
    result = self._handle_result(self._send_cmd(ServerCmd.QUERY, query))
  File "/usr/local/lib/python3.6/dist-packages/mysql/connector/connection.py", line 395, in _handle_result
    raise errors.get_exception(packet)
mysql.connector.errors.DataError: 1292 (22007): Incorrect datetime value: '' for column 'authTime' at row 1

During handling of the above exception, another exception occurred:

Traceback (most recent call last):
  File "/root/green2go/Backend/userDao.py", line 23, in addUser
    mycursor.execute(sql, val)
  File "/usr/local/lib/python3.6/dist-packages/mysql/connector/cursor.py", line 551, in execute
    self._handle_result(self._connection.cmd_query(stmt))
  File "/usr/local/lib/python3.6/dist-packages/mysql/connector/connection.py", line 490, in cmd_query
    result = self._handle_result(self._send_cmd(ServerCmd.QUERY, query))
  File "/usr/local/lib/python3.6/dist-packages/mysql/connector/connection.py", line 395, in _handle_result
    raise errors.get_exception(packet)
mysql.connector.errors.DataError: 1292 (22007): Incorrect datetime value: '' for column 'authTime' at row 1

During handling of the above exception, another exception occurred:

Traceback (most recent call last):
  File "/root/green2go/Backend/userDao.py", line 23, in addUser
    mycursor.execute(sql, val)
  File "/usr/local/lib/python3.6/dist-packages/mysql/connector/cursor.py", line 551, in execute
    self._handle_result(self._connection.cmd_query(stmt))
  File "/usr/local/lib/python3.6/dist-packages/mysql/connector/connection.py", line 490, in cmd_query
    result = self._handle_result(self._send_cmd(ServerCmd.QUERY, query))
  File "/usr/local/lib/python3.6/dist-packages/mysql/connector/connection.py", line 395, in _handle_result
    raise errors.get_exception(packet)
mysql.connector.errors.DataError: 1292 (22007): Incorrect datetime value: '' for column 'authTime' at row 1

During handling of the above exception, another exception occurred:

Traceback (most recent call last):
  File "/root/green2go/Backend/userDao.py", line 23, in addUser
    mycursor.execute(sql, val)
  File "/usr/local/lib/python3.6/dist-packages/mysql/connector/cursor.py", line 551, in execute
    self._handle_result(self._connection.cmd_query(stmt))
  File "/usr/local/lib/python3.6/dist-packages/mysql/connector/connection.py", line 490, in cmd_query
    result = self._handle_result(self._send_cmd(ServerCmd.QUERY, query))
  File "/usr/local/lib/python3.6/dist-packages/mysql/connector/connection.py", line 395, in _handle_result
    raise errors.get_exception(packet)
mysql.connector.errors.DataError: 1292 (22007): Incorrect datetime value: '' for column 'authTime' at row 1

During handling of the above exception, another exception occurred:

Traceback (most recent call last):
  File "/root/green2go/Backend/userDao.py", line 23, in addUser
    mycursor.execute(sql, val)
  File "/usr/local/lib/python3.6/dist-packages/mysql/connector/cursor.py", line 551, in execute
    self._handle_result(self._connection.cmd_query(stmt))
  File "/usr/local/lib/python3.6/dist-packages/mysql/connector/connection.py", line 490, in cmd_query
    result = self._handle_result(self._send_cmd(ServerCmd.QUERY, query))
  File "/usr/local/lib/python3.6/dist-packages/mysql/connector/connection.py", line 395, in _handle_result
    raise errors.get_exception(packet)
mysql.connector.errors.DataError: 1292 (22007): Incorrect datetime value: '' for column 'authTime' at row 1

During handling of the above exception, another exception occurred:

Traceback (most recent call last):
  File "/root/green2go/Backend/userDao.py", line 23, in addUser
    mycursor.execute(sql, val)
  File "/usr/local/lib/python3.6/dist-packages/mysql/connector/cursor.py", line 551, in execute
    self._handle_result(self._connection.cmd_query(stmt))
  File "/usr/local/lib/python3.6/dist-packages/mysql/connector/connection.py", line 490, in cmd_query
    result = self._handle_result(self._send_cmd(ServerCmd.QUERY, query))
  File "/usr/local/lib/python3.6/dist-packages/mysql/connector/connection.py", line 395, in _handle_result
    raise errors.get_exception(packet)
mysql.connector.errors.DataError: 1292 (22007): Incorrect datetime value: '' for column 'authTime' at row 1

During handling of the above exception, another exception occurred:

Traceback (most recent call last):
  File "/root/green2go/Backend/userDao.py", line 23, in addUser
    mycursor.execute(sql, val)
  File "/usr/local/lib/python3.6/dist-packages/mysql/connector/cursor.py", line 551, in execute
    self._handle_result(self._connection.cmd_query(stmt))
  File "/usr/local/lib/python3.6/dist-packages/mysql/connector/connection.py", line 490, in cmd_query
    result = self._handle_result(self._send_cmd(ServerCmd.QUERY, query))
  File "/usr/local/lib/python3.6/dist-packages/mysql/connector/connection.py", line 395, in _handle_result
    raise errors.get_exception(packet)
mysql.connector.errors.DataError: 1292 (22007): Incorrect datetime value: '' for column 'authTime' at row 1

During handling of the above exception, another exception occurred:

Traceback (most recent call last):
  File "/root/green2go/Backend/userDao.py", line 23, in addUser
    mycursor.execute(sql, val)
  File "/usr/local/lib/python3.6/dist-packages/mysql/connector/cursor.py", line 551, in execute
    self._handle_result(self._connection.cmd_query(stmt))
  File "/usr/local/lib/python3.6/dist-packages/mysql/connector/connection.py", line 490, in cmd_query
    result = self._handle_result(self._send_cmd(ServerCmd.QUERY, query))
  File "/usr/local/lib/python3.6/dist-packages/mysql/connector/connection.py", line 395, in _handle_result
    raise errors.get_exception(packet)
mysql.connector.errors.DataError: 1292 (22007): Incorrect datetime value: '' for column 'authTime' at row 1

During handling of the above exception, another exception occurred:

Traceback (most recent call last):
  File "/root/green2go/Backend/userDao.py", line 23, in addUser
    mycursor.execute(sql, val)
  File "/usr/local/lib/python3.6/dist-packages/mysql/connector/cursor.py", line 551, in execute
    self._handle_result(self._connection.cmd_query(stmt))
  File "/usr/local/lib/python3.6/dist-packages/mysql/connector/connection.py", line 490, in cmd_query
    result = self._handle_result(self._send_cmd(ServerCmd.QUERY, query))
  File "/usr/local/lib/python3.6/dist-packages/mysql/connector/connection.py", line 395, in _handle_result
    raise errors.get_exception(packet)
mysql.connector.errors.DataError: 1292 (22007): Incorrect datetime value: '' for column 'authTime' at row 1

During handling of the above exception, another exception occurred:

Traceback (most recent call last):
  File "/root/green2go/Backend/userDao.py", line 23, in addUser
    mycursor.execute(sql, val)
  File "/usr/local/lib/python3.6/dist-packages/mysql/connector/cursor.py", line 551, in execute
    self._handle_result(self._connection.cmd_query(stmt))
  File "/usr/local/lib/python3.6/dist-packages/mysql/connector/connection.py", line 490, in cmd_query
    result = self._handle_result(self._send_cmd(ServerCmd.QUERY, query))
  File "/usr/local/lib/python3.6/dist-packages/mysql/connector/connection.py", line 395, in _handle_result
    raise errors.get_exception(packet)
mysql.connector.errors.DataError: 1292 (22007): Incorrect datetime value: '' for column 'authTime' at row 1

During handling of the above exception, another exception occurred:

Traceback (most recent call last):
  File "/root/green2go/Backend/userDao.py", line 23, in addUser
    mycursor.execute(sql, val)
  File "/usr/local/lib/python3.6/dist-packages/mysql/connector/cursor.py", line 551, in execute
    self._handle_result(self._connection.cmd_query(stmt))
  File "/usr/local/lib/python3.6/dist-packages/mysql/connector/connection.py", line 490, in cmd_query
    result = self._handle_result(self._send_cmd(ServerCmd.QUERY, query))
  File "/usr/local/lib/python3.6/dist-packages/mysql/connector/connection.py", line 395, in _handle_result
    raise errors.get_exception(packet)
mysql.connector.errors.DataError: 1292 (22007): Incorrect datetime value: '' for column 'authTime' at row 1

During handling of the above exception, another exception occurred:

Traceback (most recent call last):
  File "/root/green2go/Backend/userDao.py", line 23, in addUser
    mycursor.execute(sql, val)
  File "/usr/local/lib/python3.6/dist-packages/mysql/connector/cursor.py", line 551, in execute
    self._handle_result(self._connection.cmd_query(stmt))
  File "/usr/local/lib/python3.6/dist-packages/mysql/connector/connection.py", line 490, in cmd_query
    result = self._handle_result(self._send_cmd(ServerCmd.QUERY, query))
  File "/usr/local/lib/python3.6/dist-packages/mysql/connector/connection.py", line 395, in _handle_result
    raise errors.get_exception(packet)
mysql.connector.errors.DataError: 1292 (22007): Incorrect datetime value: '' for column 'authTime' at row 1

During handling of the above exception, another exception occurred:

Traceback (most recent call last):
  File "/root/green2go/Backend/userDao.py", line 23, in addUser
    mycursor.execute(sql, val)
  File "/usr/local/lib/python3.6/dist-packages/mysql/connector/cursor.py", line 551, in execute
    self._handle_result(self._connection.cmd_query(stmt))
  File "/usr/local/lib/python3.6/dist-packages/mysql/connector/connection.py", line 490, in cmd_query
    result = self._handle_result(self._send_cmd(ServerCmd.QUERY, query))
  File "/usr/local/lib/python3.6/dist-packages/mysql/connector/connection.py", line 395, in _handle_result
    raise errors.get_exception(packet)
mysql.connector.errors.DataError: 1292 (22007): Incorrect datetime value: '' for column 'authTime' at row 1

During handling of the above exception, another exception occurred:

Traceback (most recent call last):
  File "/root/green2go/Backend/userDao.py", line 23, in addUser
    mycursor.execute(sql, val)
  File "/usr/local/lib/python3.6/dist-packages/mysql/connector/cursor.py", line 551, in execute
    self._handle_result(self._connection.cmd_query(stmt))
  File "/usr/local/lib/python3.6/dist-packages/mysql/connector/connection.py", line 490, in cmd_query
    result = self._handle_result(self._send_cmd(ServerCmd.QUERY, query))
  File "/usr/local/lib/python3.6/dist-packages/mysql/connector/connection.py", line 395, in _handle_result
    raise errors.get_exception(packet)
mysql.connector.errors.DataError: 1292 (22007): Incorrect datetime value: '' for column 'authTime' at row 1

During handling of the above exception, another exception occurred:

Traceback (most recent call last):
  File "/root/green2go/Backend/userDao.py", line 23, in addUser
    mycursor.execute(sql, val)
  File "/usr/local/lib/python3.6/dist-packages/mysql/connector/cursor.py", line 551, in execute
    self._handle_result(self._connection.cmd_query(stmt))
  File "/usr/local/lib/python3.6/dist-packages/mysql/connector/connection.py", line 490, in cmd_query
    result = self._handle_result(self._send_cmd(ServerCmd.QUERY, query))
  File "/usr/local/lib/python3.6/dist-packages/mysql/connector/connection.py", line 395, in _handle_result
    raise errors.get_exception(packet)
mysql.connector.errors.DataError: 1292 (22007): Incorrect datetime value: '' for column 'authTime' at row 1

During handling of the above exception, another exception occurred:

Traceback (most recent call last):
  File "/root/green2go/Backend/userDao.py", line 23, in addUser
    mycursor.execute(sql, val)
  File "/usr/local/lib/python3.6/dist-packages/mysql/connector/cursor.py", line 551, in execute
    self._handle_result(self._connection.cmd_query(stmt))
  File "/usr/local/lib/python3.6/dist-packages/mysql/connector/connection.py", line 490, in cmd_query
    result = self._handle_result(self._send_cmd(ServerCmd.QUERY, query))
  File "/usr/local/lib/python3.6/dist-packages/mysql/connector/connection.py", line 395, in _handle_result
    raise errors.get_exception(packet)
mysql.connector.errors.DataError: 1292 (22007): Incorrect datetime value: '' for column 'authTime' at row 1

During handling of the above exception, another exception occurred:

Traceback (most recent call last):
  File "/root/green2go/Backend/userDao.py", line 23, in addUser
    mycursor.execute(sql, val)
  File "/usr/local/lib/python3.6/dist-packages/mysql/connector/cursor.py", line 551, in execute
    self._handle_result(self._connection.cmd_query(stmt))
  File "/usr/local/lib/python3.6/dist-packages/mysql/connector/connection.py", line 490, in cmd_query
    result = self._handle_result(self._send_cmd(ServerCmd.QUERY, query))
  File "/usr/local/lib/python3.6/dist-packages/mysql/connector/connection.py", line 395, in _handle_result
    raise errors.get_exception(packet)
mysql.connector.errors.DataError: 1292 (22007): Incorrect datetime value: '' for column 'authTime' at row 1

During handling of the above exception, another exception occurred:

Traceback (most recent call last):
  File "/root/green2go/Backend/userDao.py", line 23, in addUser
    mycursor.execute(sql, val)
  File "/usr/local/lib/python3.6/dist-packages/mysql/connector/cursor.py", line 551, in execute
    self._handle_result(self._connection.cmd_query(stmt))
  File "/usr/local/lib/python3.6/dist-packages/mysql/connector/connection.py", line 490, in cmd_query
    result = self._handle_result(self._send_cmd(ServerCmd.QUERY, query))
  File "/usr/local/lib/python3.6/dist-packages/mysql/connector/connection.py", line 395, in _handle_result
    raise errors.get_exception(packet)
mysql.connector.errors.DataError: 1292 (22007): Incorrect datetime value: '' for column 'authTime' at row 1

During handling of the above exception, another exception occurred:

Traceback (most recent call last):
  File "/root/green2go/Backend/userDao.py", line 23, in addUser
    mycursor.execute(sql, val)
  File "/usr/local/lib/python3.6/dist-packages/mysql/connector/cursor.py", line 551, in execute
    self._handle_result(self._connection.cmd_query(stmt))
  File "/usr/local/lib/python3.6/dist-packages/mysql/connector/connection.py", line 490, in cmd_query
    result = self._handle_result(self._send_cmd(ServerCmd.QUERY, query))
  File "/usr/local/lib/python3.6/dist-packages/mysql/connector/connection.py", line 395, in _handle_result
    raise errors.get_exception(packet)
mysql.connector.errors.DataError: 1292 (22007): Incorrect datetime value: '' for column 'authTime' at row 1

During handling of the above exception, another exception occurred:

Traceback (most recent call last):
  File "/root/green2go/Backend/userDao.py", line 23, in addUser
    mycursor.execute(sql, val)
  File "/usr/local/lib/python3.6/dist-packages/mysql/connector/cursor.py", line 551, in execute
    self._handle_result(self._connection.cmd_query(stmt))
  File "/usr/local/lib/python3.6/dist-packages/mysql/connector/connection.py", line 490, in cmd_query
    result = self._handle_result(self._send_cmd(ServerCmd.QUERY, query))
  File "/usr/local/lib/python3.6/dist-packages/mysql/connector/connection.py", line 395, in _handle_result
    raise errors.get_exception(packet)
mysql.connector.errors.DataError: 1292 (22007): Incorrect datetime value: '' for column 'authTime' at row 1

During handling of the above exception, another exception occurred:

Traceback (most recent call last):
  File "/root/green2go/Backend/userDao.py", line 23, in addUser
    mycursor.execute(sql, val)
  File "/usr/local/lib/python3.6/dist-packages/mysql/connector/cursor.py", line 551, in execute
    self._handle_result(self._connection.cmd_query(stmt))
  File "/usr/local/lib/python3.6/dist-packages/mysql/connector/connection.py", line 490, in cmd_query
    result = self._handle_result(self._send_cmd(ServerCmd.QUERY, query))
  File "/usr/local/lib/python3.6/dist-packages/mysql/connector/connection.py", line 395, in _handle_result
    raise errors.get_exception(packet)
mysql.connector.errors.DataError: 1292 (22007): Incorrect datetime value: '' for column 'authTime' at row 1

During handling of the above exception, another exception occurred:

Traceback (most recent call last):
  File "/root/green2go/Backend/userDao.py", line 23, in addUser
    mycursor.execute(sql, val)
  File "/usr/local/lib/python3.6/dist-packages/mysql/connector/cursor.py", line 551, in execute
    self._handle_result(self._connection.cmd_query(stmt))
  File "/usr/local/lib/python3.6/dist-packages/mysql/connector/connection.py", line 490, in cmd_query
    result = self._handle_result(self._send_cmd(ServerCmd.QUERY, query))
  File "/usr/local/lib/python3.6/dist-packages/mysql/connector/connection.py", line 395, in _handle_result
    raise errors.get_exception(packet)
mysql.connector.errors.DataError: 1292 (22007): Incorrect datetime value: '' for column 'authTime' at row 1

During handling of the above exception, another exception occurred:

Traceback (most recent call last):
  File "/root/green2go/Backend/userDao.py", line 23, in addUser
    mycursor.execute(sql, val)
  File "/usr/local/lib/python3.6/dist-packages/mysql/connector/cursor.py", line 551, in execute
    self._handle_result(self._connection.cmd_query(stmt))
  File "/usr/local/lib/python3.6/dist-packages/mysql/connector/connection.py", line 490, in cmd_query
    result = self._handle_result(self._send_cmd(ServerCmd.QUERY, query))
  File "/usr/local/lib/python3.6/dist-packages/mysql/connector/connection.py", line 395, in _handle_result
    raise errors.get_exception(packet)
mysql.connector.errors.DataError: 1292 (22007): Incorrect datetime value: '' for column 'authTime' at row 1

During handling of the above exception, another exception occurred:

Traceback (most recent call last):
  File "/root/green2go/Backend/userDao.py", line 23, in addUser
    mycursor.execute(sql, val)
  File "/usr/local/lib/python3.6/dist-packages/mysql/connector/cursor.py", line 551, in execute
    self._handle_result(self._connection.cmd_query(stmt))
  File "/usr/local/lib/python3.6/dist-packages/mysql/connector/connection.py", line 490, in cmd_query
    result = self._handle_result(self._send_cmd(ServerCmd.QUERY, query))
  File "/usr/local/lib/python3.6/dist-packages/mysql/connector/connection.py", line 395, in _handle_result
    raise errors.get_exception(packet)
mysql.connector.errors.DataError: 1292 (22007): Incorrect datetime value: '' for column 'authTime' at row 1

During handling of the above exception, another exception occurred:

Traceback (most recent call last):
  File "/root/green2go/Backend/userDao.py", line 23, in addUser
    mycursor.execute(sql, val)
  File "/usr/local/lib/python3.6/dist-packages/mysql/connector/cursor.py", line 551, in execute
    self._handle_result(self._connection.cmd_query(stmt))
  File "/usr/local/lib/python3.6/dist-packages/mysql/connector/connection.py", line 490, in cmd_query
    result = self._handle_result(self._send_cmd(ServerCmd.QUERY, query))
  File "/usr/local/lib/python3.6/dist-packages/mysql/connector/connection.py", line 395, in _handle_result
    raise errors.get_exception(packet)
mysql.connector.errors.DataError: 1292 (22007): Incorrect datetime value: '' for column 'authTime' at row 1

During handling of the above exception, another exception occurred:

Traceback (most recent call last):
  File "/root/green2go/Backend/userDao.py", line 23, in addUser
    mycursor.execute(sql, val)
  File "/usr/local/lib/python3.6/dist-packages/mysql/connector/cursor.py", line 551, in execute
    self._handle_result(self._connection.cmd_query(stmt))
  File "/usr/local/lib/python3.6/dist-packages/mysql/connector/connection.py", line 490, in cmd_query
    result = self._handle_result(self._send_cmd(ServerCmd.QUERY, query))
  File "/usr/local/lib/python3.6/dist-packages/mysql/connector/connection.py", line 395, in _handle_result
    raise errors.get_exception(packet)
mysql.connector.errors.DataError: 1292 (22007): Incorrect datetime value: '' for column 'authTime' at row 1

During handling of the above exception, another exception occurred:

Traceback (most recent call last):
  File "/root/green2go/Backend/userDao.py", line 23, in addUser
    mycursor.execute(sql, val)
  File "/usr/local/lib/python3.6/dist-packages/mysql/connector/cursor.py", line 551, in execute
    self._handle_result(self._connection.cmd_query(stmt))
  File "/usr/local/lib/python3.6/dist-packages/mysql/connector/connection.py", line 490, in cmd_query
    result = self._handle_result(self._send_cmd(ServerCmd.QUERY, query))
  File "/usr/local/lib/python3.6/dist-packages/mysql/connector/connection.py", line 395, in _handle_result
    raise errors.get_exception(packet)
mysql.connector.errors.DataError: 1292 (22007): Incorrect datetime value: '' for column 'authTime' at row 1

During handling of the above exception, another exception occurred:

Traceback (most recent call last):
  File "/root/green2go/Backend/userDao.py", line 23, in addUser
    mycursor.execute(sql, val)
  File "/usr/local/lib/python3.6/dist-packages/mysql/connector/cursor.py", line 551, in execute
    self._handle_result(self._connection.cmd_query(stmt))
  File "/usr/local/lib/python3.6/dist-packages/mysql/connector/connection.py", line 490, in cmd_query
    result = self._handle_result(self._send_cmd(ServerCmd.QUERY, query))
  File "/usr/local/lib/python3.6/dist-packages/mysql/connector/connection.py", line 395, in _handle_result
    raise errors.get_exception(packet)
mysql.connector.errors.DataError: 1292 (22007): Incorrect datetime value: '' for column 'authTime' at row 1

During handling of the above exception, another exception occurred:

Traceback (most recent call last):
  File "/root/green2go/Backend/userDao.py", line 23, in addUser
    mycursor.execute(sql, val)
  File "/usr/local/lib/python3.6/dist-packages/mysql/connector/cursor.py", line 551, in execute
    self._handle_result(self._connection.cmd_query(stmt))
  File "/usr/local/lib/python3.6/dist-packages/mysql/connector/connection.py", line 490, in cmd_query
    result = self._handle_result(self._send_cmd(ServerCmd.QUERY, query))
  File "/usr/local/lib/python3.6/dist-packages/mysql/connector/connection.py", line 395, in _handle_result
    raise errors.get_exception(packet)
mysql.connector.errors.DataError: 1292 (22007): Incorrect datetime value: '' for column 'authTime' at row 1

During handling of the above exception, another exception occurred:

Traceback (most recent call last):
  File "/root/green2go/Backend/userDao.py", line 23, in addUser
    mycursor.execute(sql, val)
  File "/usr/local/lib/python3.6/dist-packages/mysql/connector/cursor.py", line 551, in execute
    self._handle_result(self._connection.cmd_query(stmt))
  File "/usr/local/lib/python3.6/dist-packages/mysql/connector/connection.py", line 490, in cmd_query
    result = self._handle_result(self._send_cmd(ServerCmd.QUERY, query))
  File "/usr/local/lib/python3.6/dist-packages/mysql/connector/connection.py", line 395, in _handle_result
    raise errors.get_exception(packet)
mysql.connector.errors.DataError: 1292 (22007): Incorrect datetime value: '' for column 'authTime' at row 1

During handling of the above exception, another exception occurred:

Traceback (most recent call last):
  File "/root/green2go/Backend/userDao.py", line 23, in addUser
    mycursor.execute(sql, val)
  File "/usr/local/lib/python3.6/dist-packages/mysql/connector/cursor.py", line 551, in execute
    self._handle_result(self._connection.cmd_query(stmt))
  File "/usr/local/lib/python3.6/dist-packages/mysql/connector/connection.py", line 490, in cmd_query
    result = self._handle_result(self._send_cmd(ServerCmd.QUERY, query))
  File "/usr/local/lib/python3.6/dist-packages/mysql/connector/connection.py", line 395, in _handle_result
    raise errors.get_exception(packet)
mysql.connector.errors.DataError: 1292 (22007): Incorrect datetime value: '' for column 'authTime' at row 1

During handling of the above exception, another exception occurred:

Traceback (most recent call last):
  File "/root/green2go/Backend/userDao.py", line 23, in addUser
    mycursor.execute(sql, val)
  File "/usr/local/lib/python3.6/dist-packages/mysql/connector/cursor.py", line 551, in execute
    self._handle_result(self._connection.cmd_query(stmt))
  File "/usr/local/lib/python3.6/dist-packages/mysql/connector/connection.py", line 490, in cmd_query
    result = self._handle_result(self._send_cmd(ServerCmd.QUERY, query))
  File "/usr/local/lib/python3.6/dist-packages/mysql/connector/connection.py", line 395, in _handle_result
    raise errors.get_exception(packet)
mysql.connector.errors.DataError: 1292 (22007): Incorrect datetime value: '' for column 'authTime' at row 1

During handling of the above exception, another exception occurred:

Traceback (most recent call last):
  File "/root/green2go/Backend/userDao.py", line 23, in addUser
    mycursor.execute(sql, val)
  File "/usr/local/lib/python3.6/dist-packages/mysql/connector/cursor.py", line 551, in execute
    self._handle_result(self._connection.cmd_query(stmt))
  File "/usr/local/lib/python3.6/dist-packages/mysql/connector/connection.py", line 490, in cmd_query
    result = self._handle_result(self._send_cmd(ServerCmd.QUERY, query))
  File "/usr/local/lib/python3.6/dist-packages/mysql/connector/connection.py", line 395, in _handle_result
    raise errors.get_exception(packet)
mysql.connector.errors.DataError: 1292 (22007): Incorrect datetime value: '' for column 'authTime' at row 1

During handling of the above exception, another exception occurred:

Traceback (most recent call last):
  File "/root/green2go/Backend/userDao.py", line 23, in addUser
    mycursor.execute(sql, val)
  File "/usr/local/lib/python3.6/dist-packages/mysql/connector/cursor.py", line 551, in execute
    self._handle_result(self._connection.cmd_query(stmt))
  File "/usr/local/lib/python3.6/dist-packages/mysql/connector/connection.py", line 490, in cmd_query
    result = self._handle_result(self._send_cmd(ServerCmd.QUERY, query))
  File "/usr/local/lib/python3.6/dist-packages/mysql/connector/connection.py", line 395, in _handle_result
    raise errors.get_exception(packet)
mysql.connector.errors.DataError: 1292 (22007): Incorrect datetime value: '' for column 'authTime' at row 1

During handling of the above exception, another exception occurred:

Traceback (most recent call last):
  File "/root/green2go/Backend/userDao.py", line 23, in addUser
    mycursor.execute(sql, val)
  File "/usr/local/lib/python3.6/dist-packages/mysql/connector/cursor.py", line 551, in execute
    self._handle_result(self._connection.cmd_query(stmt))
  File "/usr/local/lib/python3.6/dist-packages/mysql/connector/connection.py", line 490, in cmd_query
    result = self._handle_result(self._send_cmd(ServerCmd.QUERY, query))
  File "/usr/local/lib/python3.6/dist-packages/mysql/connector/connection.py", line 395, in _handle_result
    raise errors.get_exception(packet)
mysql.connector.errors.DataError: 1292 (22007): Incorrect datetime value: '' for column 'authTime' at row 1

During handling of the above exception, another exception occurred:

Traceback (most recent call last):
  File "/root/green2go/Backend/userDao.py", line 23, in addUser
    mycursor.execute(sql, val)
  File "/usr/local/lib/python3.6/dist-packages/mysql/connector/cursor.py", line 551, in execute
    self._handle_result(self._connection.cmd_query(stmt))
  File "/usr/local/lib/python3.6/dist-packages/mysql/connector/connection.py", line 490, in cmd_query
    result = self._handle_result(self._send_cmd(ServerCmd.QUERY, query))
  File "/usr/local/lib/python3.6/dist-packages/mysql/connector/connection.py", line 395, in _handle_result
    raise errors.get_exception(packet)
mysql.connector.errors.DataError: 1292 (22007): Incorrect datetime value: '' for column 'authTime' at row 1

During handling of the above exception, another exception occurred:

Traceback (most recent call last):
  File "/root/green2go/Backend/userDao.py", line 23, in addUser
    mycursor.execute(sql, val)
  File "/usr/local/lib/python3.6/dist-packages/mysql/connector/cursor.py", line 551, in execute
    self._handle_result(self._connection.cmd_query(stmt))
  File "/usr/local/lib/python3.6/dist-packages/mysql/connector/connection.py", line 490, in cmd_query
    result = self._handle_result(self._send_cmd(ServerCmd.QUERY, query))
  File "/usr/local/lib/python3.6/dist-packages/mysql/connector/connection.py", line 395, in _handle_result
    raise errors.get_exception(packet)
mysql.connector.errors.DataError: 1292 (22007): Incorrect datetime value: '' for column 'authTime' at row 1

During handling of the above exception, another exception occurred:

Traceback (most recent call last):
  File "/root/green2go/Backend/userDao.py", line 23, in addUser
    mycursor.execute(sql, val)
  File "/usr/local/lib/python3.6/dist-packages/mysql/connector/cursor.py", line 551, in execute
    self._handle_result(self._connection.cmd_query(stmt))
  File "/usr/local/lib/python3.6/dist-packages/mysql/connector/connection.py", line 490, in cmd_query
    result = self._handle_result(self._send_cmd(ServerCmd.QUERY, query))
  File "/usr/local/lib/python3.6/dist-packages/mysql/connector/connection.py", line 395, in _handle_result
    raise errors.get_exception(packet)
mysql.connector.errors.DataError: 1292 (22007): Incorrect datetime value: '' for column 'authTime' at row 1

During handling of the above exception, another exception occurred:

Traceback (most recent call last):
  File "/root/green2go/Backend/userDao.py", line 23, in addUser
    mycursor.execute(sql, val)
  File "/usr/local/lib/python3.6/dist-packages/mysql/connector/cursor.py", line 551, in execute
    self._handle_result(self._connection.cmd_query(stmt))
  File "/usr/local/lib/python3.6/dist-packages/mysql/connector/connection.py", line 490, in cmd_query
    result = self._handle_result(self._send_cmd(ServerCmd.QUERY, query))
  File "/usr/local/lib/python3.6/dist-packages/mysql/connector/connection.py", line 395, in _handle_result
    raise errors.get_exception(packet)
mysql.connector.errors.DataError: 1292 (22007): Incorrect datetime value: '' for column 'authTime' at row 1

During handling of the above exception, another exception occurred:

Traceback (most recent call last):
  File "/root/green2go/Backend/userDao.py", line 23, in addUser
    mycursor.execute(sql, val)
  File "/usr/local/lib/python3.6/dist-packages/mysql/connector/cursor.py", line 551, in execute
    self._handle_result(self._connection.cmd_query(stmt))
  File "/usr/local/lib/python3.6/dist-packages/mysql/connector/connection.py", line 490, in cmd_query
    result = self._handle_result(self._send_cmd(ServerCmd.QUERY, query))
  File "/usr/local/lib/python3.6/dist-packages/mysql/connector/connection.py", line 395, in _handle_result
    raise errors.get_exception(packet)
mysql.connector.errors.DataError: 1292 (22007): Incorrect datetime value: '' for column 'authTime' at row 1

During handling of the above exception, another exception occurred:

Traceback (most recent call last):
  File "/root/green2go/Backend/userDao.py", line 23, in addUser
    mycursor.execute(sql, val)
  File "/usr/local/lib/python3.6/dist-packages/mysql/connector/cursor.py", line 551, in execute
    self._handle_result(self._connection.cmd_query(stmt))
  File "/usr/local/lib/python3.6/dist-packages/mysql/connector/connection.py", line 490, in cmd_query
    result = self._handle_result(self._send_cmd(ServerCmd.QUERY, query))
  File "/usr/local/lib/python3.6/dist-packages/mysql/connector/connection.py", line 395, in _handle_result
    raise errors.get_exception(packet)
mysql.connector.errors.DataError: 1292 (22007): Incorrect datetime value: '' for column 'authTime' at row 1

During handling of the above exception, another exception occurred:

Traceback (most recent call last):
  File "/root/green2go/Backend/userDao.py", line 23, in addUser
    mycursor.execute(sql, val)
  File "/usr/local/lib/python3.6/dist-packages/mysql/connector/cursor.py", line 551, in execute
    self._handle_result(self._connection.cmd_query(stmt))
  File "/usr/local/lib/python3.6/dist-packages/mysql/connector/connection.py", line 490, in cmd_query
    result = self._handle_result(self._send_cmd(ServerCmd.QUERY, query))
  File "/usr/local/lib/python3.6/dist-packages/mysql/connector/connection.py", line 395, in _handle_result
    raise errors.get_exception(packet)
mysql.connector.errors.DataError: 1292 (22007): Incorrect datetime value: '' for column 'authTime' at row 1

During handling of the above exception, another exception occurred:

Traceback (most recent call last):
  File "/root/green2go/Backend/userDao.py", line 23, in addUser
    mycursor.execute(sql, val)
  File "/usr/local/lib/python3.6/dist-packages/mysql/connector/cursor.py", line 551, in execute
    self._handle_result(self._connection.cmd_query(stmt))
  File "/usr/local/lib/python3.6/dist-packages/mysql/connector/connection.py", line 490, in cmd_query
    result = self._handle_result(self._send_cmd(ServerCmd.QUERY, query))
  File "/usr/local/lib/python3.6/dist-packages/mysql/connector/connection.py", line 395, in _handle_result
    raise errors.get_exception(packet)
mysql.connector.errors.DataError: 1292 (22007): Incorrect datetime value: '' for column 'authTime' at row 1

During handling of the above exception, another exception occurred:

Traceback (most recent call last):
  File "/root/green2go/Backend/userDao.py", line 23, in addUser
    mycursor.execute(sql, val)
  File "/usr/local/lib/python3.6/dist-packages/mysql/connector/cursor.py", line 551, in execute
    self._handle_result(self._connection.cmd_query(stmt))
  File "/usr/local/lib/python3.6/dist-packages/mysql/connector/connection.py", line 490, in cmd_query
    result = self._handle_result(self._send_cmd(ServerCmd.QUERY, query))
  File "/usr/local/lib/python3.6/dist-packages/mysql/connector/connection.py", line 395, in _handle_result
    raise errors.get_exception(packet)
mysql.connector.errors.DataError: 1292 (22007): Incorrect datetime value: '' for column 'authTime' at row 1

During handling of the above exception, another exception occurred:

Traceback (most recent call last):
  File "/root/green2go/Backend/userDao.py", line 23, in addUser
    mycursor.execute(sql, val)
  File "/usr/local/lib/python3.6/dist-packages/mysql/connector/cursor.py", line 551, in execute
    self._handle_result(self._connection.cmd_query(stmt))
  File "/usr/local/lib/python3.6/dist-packages/mysql/connector/connection.py", line 490, in cmd_query
    result = self._handle_result(self._send_cmd(ServerCmd.QUERY, query))
  File "/usr/local/lib/python3.6/dist-packages/mysql/connector/connection.py", line 395, in _handle_result
    raise errors.get_exception(packet)
mysql.connector.errors.DataError: 1292 (22007): Incorrect datetime value: '' for column 'authTime' at row 1

During handling of the above exception, another exception occurred:

Traceback (most recent call last):
  File "/root/green2go/Backend/userDao.py", line 23, in addUser
    mycursor.execute(sql, val)
  File "/usr/local/lib/python3.6/dist-packages/mysql/connector/cursor.py", line 551, in execute
    self._handle_result(self._connection.cmd_query(stmt))
  File "/usr/local/lib/python3.6/dist-packages/mysql/connector/connection.py", line 490, in cmd_query
    result = self._handle_result(self._send_cmd(ServerCmd.QUERY, query))
  File "/usr/local/lib/python3.6/dist-packages/mysql/connector/connection.py", line 395, in _handle_result
    raise errors.get_exception(packet)
mysql.connector.errors.DataError: 1292 (22007): Incorrect datetime value: '' for column 'authTime' at row 1

During handling of the above exception, another exception occurred:

Traceback (most recent call last):
  File "/root/green2go/Backend/userDao.py", line 23, in addUser
    mycursor.execute(sql, val)
  File "/usr/local/lib/python3.6/dist-packages/mysql/connector/cursor.py", line 551, in execute
    self._handle_result(self._connection.cmd_query(stmt))
  File "/usr/local/lib/python3.6/dist-packages/mysql/connector/connection.py", line 490, in cmd_query
    result = self._handle_result(self._send_cmd(ServerCmd.QUERY, query))
  File "/usr/local/lib/python3.6/dist-packages/mysql/connector/connection.py", line 395, in _handle_result
    raise errors.get_exception(packet)
mysql.connector.errors.DataError: 1292 (22007): Incorrect datetime value: '' for column 'authTime' at row 1

During handling of the above exception, another exception occurred:

Traceback (most recent call last):
  File "/root/green2go/Backend/userDao.py", line 23, in addUser
    mycursor.execute(sql, val)
  File "/usr/local/lib/python3.6/dist-packages/mysql/connector/cursor.py", line 551, in execute
    self._handle_result(self._connection.cmd_query(stmt))
  File "/usr/local/lib/python3.6/dist-packages/mysql/connector/connection.py", line 490, in cmd_query
    result = self._handle_result(self._send_cmd(ServerCmd.QUERY, query))
  File "/usr/local/lib/python3.6/dist-packages/mysql/connector/connection.py", line 395, in _handle_result
    raise errors.get_exception(packet)
mysql.connector.errors.DataError: 1292 (22007): Incorrect datetime value: '' for column 'authTime' at row 1

During handling of the above exception, another exception occurred:

Traceback (most recent call last):
  File "/root/green2go/Backend/userDao.py", line 23, in addUser
    mycursor.execute(sql, val)
  File "/usr/local/lib/python3.6/dist-packages/mysql/connector/cursor.py", line 551, in execute
    self._handle_result(self._connection.cmd_query(stmt))
  File "/usr/local/lib/python3.6/dist-packages/mysql/connector/connection.py", line 490, in cmd_query
    result = self._handle_result(self._send_cmd(ServerCmd.QUERY, query))
  File "/usr/local/lib/python3.6/dist-packages/mysql/connector/connection.py", line 395, in _handle_result
    raise errors.get_exception(packet)
mysql.connector.errors.DataError: 1292 (22007): Incorrect datetime value: '' for column 'authTime' at row 1

During handling of the above exception, another exception occurred:

Traceback (most recent call last):
  File "/root/green2go/Backend/userDao.py", line 23, in addUser
    mycursor.execute(sql, val)
  File "/usr/local/lib/python3.6/dist-packages/mysql/connector/cursor.py", line 551, in execute
    self._handle_result(self._connection.cmd_query(stmt))
  File "/usr/local/lib/python3.6/dist-packages/mysql/connector/connection.py", line 490, in cmd_query
    result = self._handle_result(self._send_cmd(ServerCmd.QUERY, query))
  File "/usr/local/lib/python3.6/dist-packages/mysql/connector/connection.py", line 395, in _handle_result
    raise errors.get_exception(packet)
mysql.connector.errors.DataError: 1292 (22007): Incorrect datetime value: '' for column 'authTime' at row 1

During handling of the above exception, another exception occurred:

Traceback (most recent call last):
  File "/root/green2go/Backend/userDao.py", line 23, in addUser
    mycursor.execute(sql, val)
  File "/usr/local/lib/python3.6/dist-packages/mysql/connector/cursor.py", line 551, in execute
    self._handle_result(self._connection.cmd_query(stmt))
  File "/usr/local/lib/python3.6/dist-packages/mysql/connector/connection.py", line 490, in cmd_query
    result = self._handle_result(self._send_cmd(ServerCmd.QUERY, query))
  File "/usr/local/lib/python3.6/dist-packages/mysql/connector/connection.py", line 395, in _handle_result
    raise errors.get_exception(packet)
mysql.connector.errors.DataError: 1292 (22007): Incorrect datetime value: '' for column 'authTime' at row 1

During handling of the above exception, another exception occurred:

Traceback (most recent call last):
  File "/root/green2go/Backend/userDao.py", line 23, in addUser
    mycursor.execute(sql, val)
  File "/usr/local/lib/python3.6/dist-packages/mysql/connector/cursor.py", line 551, in execute
    self._handle_result(self._connection.cmd_query(stmt))
  File "/usr/local/lib/python3.6/dist-packages/mysql/connector/connection.py", line 490, in cmd_query
    result = self._handle_result(self._send_cmd(ServerCmd.QUERY, query))
  File "/usr/local/lib/python3.6/dist-packages/mysql/connector/connection.py", line 395, in _handle_result
    raise errors.get_exception(packet)
mysql.connector.errors.DataError: 1292 (22007): Incorrect datetime value: '' for column 'authTime' at row 1

During handling of the above exception, another exception occurred:

Traceback (most recent call last):
  File "/root/green2go/Backend/userDao.py", line 23, in addUser
    mycursor.execute(sql, val)
  File "/usr/local/lib/python3.6/dist-packages/mysql/connector/cursor.py", line 551, in execute
    self._handle_result(self._connection.cmd_query(stmt))
  File "/usr/local/lib/python3.6/dist-packages/mysql/connector/connection.py", line 490, in cmd_query
    result = self._handle_result(self._send_cmd(ServerCmd.QUERY, query))
  File "/usr/local/lib/python3.6/dist-packages/mysql/connector/connection.py", line 395, in _handle_result
    raise errors.get_exception(packet)
mysql.connector.errors.DataError: 1292 (22007): Incorrect datetime value: '' for column 'authTime' at row 1

During handling of the above exception, another exception occurred:

Traceback (most recent call last):
  File "/root/green2go/Backend/userDao.py", line 23, in addUser
    mycursor.execute(sql, val)
  File "/usr/local/lib/python3.6/dist-packages/mysql/connector/cursor.py", line 551, in execute
    self._handle_result(self._connection.cmd_query(stmt))
  File "/usr/local/lib/python3.6/dist-packages/mysql/connector/connection.py", line 490, in cmd_query
    result = self._handle_result(self._send_cmd(ServerCmd.QUERY, query))
  File "/usr/local/lib/python3.6/dist-packages/mysql/connector/connection.py", line 395, in _handle_result
    raise errors.get_exception(packet)
mysql.connector.errors.DataError: 1292 (22007): Incorrect datetime value: '' for column 'authTime' at row 1

During handling of the above exception, another exception occurred:

Traceback (most recent call last):
  File "/root/green2go/Backend/userDao.py", line 23, in addUser
    mycursor.execute(sql, val)
  File "/usr/local/lib/python3.6/dist-packages/mysql/connector/cursor.py", line 551, in execute
    self._handle_result(self._connection.cmd_query(stmt))
  File "/usr/local/lib/python3.6/dist-packages/mysql/connector/connection.py", line 490, in cmd_query
    result = self._handle_result(self._send_cmd(ServerCmd.QUERY, query))
  File "/usr/local/lib/python3.6/dist-packages/mysql/connector/connection.py", line 395, in _handle_result
    raise errors.get_exception(packet)
mysql.connector.errors.DataError: 1292 (22007): Incorrect datetime value: '' for column 'authTime' at row 1

During handling of the above exception, another exception occurred:

Traceback (most recent call last):
  File "/root/green2go/Backend/userDao.py", line 23, in addUser
    mycursor.execute(sql, val)
  File "/usr/local/lib/python3.6/dist-packages/mysql/connector/cursor.py", line 551, in execute
    self._handle_result(self._connection.cmd_query(stmt))
  File "/usr/local/lib/python3.6/dist-packages/mysql/connector/connection.py", line 490, in cmd_query
    result = self._handle_result(self._send_cmd(ServerCmd.QUERY, query))
  File "/usr/local/lib/python3.6/dist-packages/mysql/connector/connection.py", line 395, in _handle_result
    raise errors.get_exception(packet)
mysql.connector.errors.DataError: 1292 (22007): Incorrect datetime value: '' for column 'authTime' at row 1

During handling of the above exception, another exception occurred:

Traceback (most recent call last):
  File "/root/green2go/Backend/userDao.py", line 23, in addUser
    mycursor.execute(sql, val)
  File "/usr/local/lib/python3.6/dist-packages/mysql/connector/cursor.py", line 551, in execute
    self._handle_result(self._connection.cmd_query(stmt))
  File "/usr/local/lib/python3.6/dist-packages/mysql/connector/connection.py", line 490, in cmd_query
    result = self._handle_result(self._send_cmd(ServerCmd.QUERY, query))
  File "/usr/local/lib/python3.6/dist-packages/mysql/connector/connection.py", line 395, in _handle_result
    raise errors.get_exception(packet)
mysql.connector.errors.DataError: 1292 (22007): Incorrect datetime value: '' for column 'authTime' at row 1

During handling of the above exception, another exception occurred:

Traceback (most recent call last):
  File "/root/green2go/Backend/userDao.py", line 23, in addUser
    mycursor.execute(sql, val)
  File "/usr/local/lib/python3.6/dist-packages/mysql/connector/cursor.py", line 551, in execute
    self._handle_result(self._connection.cmd_query(stmt))
  File "/usr/local/lib/python3.6/dist-packages/mysql/connector/connection.py", line 490, in cmd_query
    result = self._handle_result(self._send_cmd(ServerCmd.QUERY, query))
  File "/usr/local/lib/python3.6/dist-packages/mysql/connector/connection.py", line 395, in _handle_result
    raise errors.get_exception(packet)
mysql.connector.errors.DataError: 1292 (22007): Incorrect datetime value: '' for column 'authTime' at row 1

During handling of the above exception, another exception occurred:

Traceback (most recent call last):
  File "/root/green2go/Backend/userDao.py", line 23, in addUser
    mycursor.execute(sql, val)
  File "/usr/local/lib/python3.6/dist-packages/mysql/connector/cursor.py", line 551, in execute
    self._handle_result(self._connection.cmd_query(stmt))
  File "/usr/local/lib/python3.6/dist-packages/mysql/connector/connection.py", line 490, in cmd_query
    result = self._handle_result(self._send_cmd(ServerCmd.QUERY, query))
  File "/usr/local/lib/python3.6/dist-packages/mysql/connector/connection.py", line 395, in _handle_result
    raise errors.get_exception(packet)
mysql.connector.errors.DataError: 1292 (22007): Incorrect datetime value: '' for column 'authTime' at row 1

During handling of the above exception, another exception occurred:

Traceback (most recent call last):
  File "/root/green2go/Backend/userDao.py", line 23, in addUser
    mycursor.execute(sql, val)
  File "/usr/local/lib/python3.6/dist-packages/mysql/connector/cursor.py", line 551, in execute
    self._handle_result(self._connection.cmd_query(stmt))
  File "/usr/local/lib/python3.6/dist-packages/mysql/connector/connection.py", line 490, in cmd_query
    result = self._handle_result(self._send_cmd(ServerCmd.QUERY, query))
  File "/usr/local/lib/python3.6/dist-packages/mysql/connector/connection.py", line 395, in _handle_result
    raise errors.get_exception(packet)
mysql.connector.errors.DataError: 1292 (22007): Incorrect datetime value: '' for column 'authTime' at row 1

During handling of the above exception, another exception occurred:

Traceback (most recent call last):
  File "/root/green2go/Backend/userDao.py", line 23, in addUser
    mycursor.execute(sql, val)
  File "/usr/local/lib/python3.6/dist-packages/mysql/connector/cursor.py", line 551, in execute
    self._handle_result(self._connection.cmd_query(stmt))
  File "/usr/local/lib/python3.6/dist-packages/mysql/connector/connection.py", line 490, in cmd_query
    result = self._handle_result(self._send_cmd(ServerCmd.QUERY, query))
  File "/usr/local/lib/python3.6/dist-packages/mysql/connector/connection.py", line 395, in _handle_result
    raise errors.get_exception(packet)
mysql.connector.errors.DataError: 1292 (22007): Incorrect datetime value: '' for column 'authTime' at row 1

During handling of the above exception, another exception occurred:

Traceback (most recent call last):
  File "/root/green2go/Backend/userDao.py", line 23, in addUser
    mycursor.execute(sql, val)
  File "/usr/local/lib/python3.6/dist-packages/mysql/connector/cursor.py", line 551, in execute
    self._handle_result(self._connection.cmd_query(stmt))
  File "/usr/local/lib/python3.6/dist-packages/mysql/connector/connection.py", line 490, in cmd_query
    result = self._handle_result(self._send_cmd(ServerCmd.QUERY, query))
  File "/usr/local/lib/python3.6/dist-packages/mysql/connector/connection.py", line 395, in _handle_result
    raise errors.get_exception(packet)
mysql.connector.errors.DataError: 1292 (22007): Incorrect datetime value: '' for column 'authTime' at row 1

During handling of the above exception, another exception occurred:

Traceback (most recent call last):
  File "/root/green2go/Backend/userDao.py", line 23, in addUser
    mycursor.execute(sql, val)
  File "/usr/local/lib/python3.6/dist-packages/mysql/connector/cursor.py", line 551, in execute
    self._handle_result(self._connection.cmd_query(stmt))
  File "/usr/local/lib/python3.6/dist-packages/mysql/connector/connection.py", line 490, in cmd_query
    result = self._handle_result(self._send_cmd(ServerCmd.QUERY, query))
  File "/usr/local/lib/python3.6/dist-packages/mysql/connector/connection.py", line 395, in _handle_result
    raise errors.get_exception(packet)
mysql.connector.errors.DataError: 1292 (22007): Incorrect datetime value: '' for column 'authTime' at row 1

During handling of the above exception, another exception occurred:

Traceback (most recent call last):
  File "/root/green2go/Backend/userDao.py", line 23, in addUser
    mycursor.execute(sql, val)
  File "/usr/local/lib/python3.6/dist-packages/mysql/connector/cursor.py", line 551, in execute
    self._handle_result(self._connection.cmd_query(stmt))
  File "/usr/local/lib/python3.6/dist-packages/mysql/connector/connection.py", line 490, in cmd_query
    result = self._handle_result(self._send_cmd(ServerCmd.QUERY, query))
  File "/usr/local/lib/python3.6/dist-packages/mysql/connector/connection.py", line 395, in _handle_result
    raise errors.get_exception(packet)
mysql.connector.errors.DataError: 1292 (22007): Incorrect datetime value: '' for column 'authTime' at row 1

During handling of the above exception, another exception occurred:

Traceback (most recent call last):
  File "/root/green2go/Backend/userDao.py", line 23, in addUser
    mycursor.execute(sql, val)
  File "/usr/local/lib/python3.6/dist-packages/mysql/connector/cursor.py", line 551, in execute
    self._handle_result(self._connection.cmd_query(stmt))
  File "/usr/local/lib/python3.6/dist-packages/mysql/connector/connection.py", line 490, in cmd_query
    result = self._handle_result(self._send_cmd(ServerCmd.QUERY, query))
  File "/usr/local/lib/python3.6/dist-packages/mysql/connector/connection.py", line 395, in _handle_result
    raise errors.get_exception(packet)
mysql.connector.errors.DataError: 1292 (22007): Incorrect datetime value: '' for column 'authTime' at row 1

During handling of the above exception, another exception occurred:

Traceback (most recent call last):
  File "/root/green2go/Backend/userDao.py", line 23, in addUser
    mycursor.execute(sql, val)
  File "/usr/local/lib/python3.6/dist-packages/mysql/connector/cursor.py", line 551, in execute
    self._handle_result(self._connection.cmd_query(stmt))
  File "/usr/local/lib/python3.6/dist-packages/mysql/connector/connection.py", line 490, in cmd_query
    result = self._handle_result(self._send_cmd(ServerCmd.QUERY, query))
  File "/usr/local/lib/python3.6/dist-packages/mysql/connector/connection.py", line 395, in _handle_result
    raise errors.get_exception(packet)
mysql.connector.errors.DataError: 1292 (22007): Incorrect datetime value: '' for column 'authTime' at row 1

During handling of the above exception, another exception occurred:

Traceback (most recent call last):
  File "/root/green2go/Backend/userDao.py", line 23, in addUser
    mycursor.execute(sql, val)
  File "/usr/local/lib/python3.6/dist-packages/mysql/connector/cursor.py", line 551, in execute
    self._handle_result(self._connection.cmd_query(stmt))
  File "/usr/local/lib/python3.6/dist-packages/mysql/connector/connection.py", line 490, in cmd_query
    result = self._handle_result(self._send_cmd(ServerCmd.QUERY, query))
  File "/usr/local/lib/python3.6/dist-packages/mysql/connector/connection.py", line 395, in _handle_result
    raise errors.get_exception(packet)
mysql.connector.errors.DataError: 1292 (22007): Incorrect datetime value: '' for column 'authTime' at row 1

During handling of the above exception, another exception occurred:

Traceback (most recent call last):
  File "/root/green2go/Backend/userDao.py", line 23, in addUser
    mycursor.execute(sql, val)
  File "/usr/local/lib/python3.6/dist-packages/mysql/connector/cursor.py", line 551, in execute
    self._handle_result(self._connection.cmd_query(stmt))
  File "/usr/local/lib/python3.6/dist-packages/mysql/connector/connection.py", line 490, in cmd_query
    result = self._handle_result(self._send_cmd(ServerCmd.QUERY, query))
  File "/usr/local/lib/python3.6/dist-packages/mysql/connector/connection.py", line 395, in _handle_result
    raise errors.get_exception(packet)
mysql.connector.errors.DataError: 1292 (22007): Incorrect datetime value: '' for column 'authTime' at row 1

During handling of the above exception, another exception occurred:

Traceback (most recent call last):
  File "/usr/local/lib/python3.6/dist-packages/flask/app.py", line 2447, in wsgi_app
    response = self.full_dispatch_request()
  File "/usr/local/lib/python3.6/dist-packages/flask/app.py", line 1952, in full_dispatch_request
    rv = self.handle_user_exception(e)
  File "/usr/local/lib/python3.6/dist-packages/flask/app.py", line 1821, in handle_user_exception
    reraise(exc_type, exc_value, tb)
  File "/usr/local/lib/python3.6/dist-packages/flask/_compat.py", line 39, in reraise
    raise value
  File "/usr/local/lib/python3.6/dist-packages/flask/app.py", line 1950, in full_dispatch_request
    rv = self.dispatch_request()
  File "/usr/local/lib/python3.6/dist-packages/flask/app.py", line 1936, in dispatch_request
    return self.view_functions[rule.endpoint](**req.view_args)
  File "runBackend.py", line 47, in addUser
    res = dao.addUser(newUser)
  File "/root/green2go/Backend/userDao.py", line 29, in addUser
    return self.addUser(val)
  File "/root/green2go/Backend/userDao.py", line 29, in addUser
    return self.addUser(val)
  File "/root/green2go/Backend/userDao.py", line 29, in addUser
    return self.addUser(val)
  [Previous line repeated 144 more times]
  File "/root/green2go/Backend/userDao.py", line 28, in addUser
    self.reconnectSql()
  File "/root/green2go/Backend/userDao.py", line 16, in reconnectSql
    database="sys")
  File "/usr/local/lib/python3.6/dist-packages/mysql/connector/__init__.py", line 179, in connect
    return MySQLConnection(*args, **kwargs)
  File "/usr/local/lib/python3.6/dist-packages/mysql/connector/connection.py", line 95, in __init__
    self.connect(**kwargs)
  File "/usr/local/lib/python3.6/dist-packages/mysql/connector/abstracts.py", line 716, in connect
    self._open_connection()
  File "/usr/local/lib/python3.6/dist-packages/mysql/connector/connection.py", line 207, in _open_connection
    self._do_handshake()
  File "/usr/local/lib/python3.6/dist-packages/mysql/connector/connection.py", line 101, in _do_handshake
    raise errors.get_exception(packet)
mysql.connector.errors.DatabaseError: 1040: Too many connections
204.144.15.24 - - [18/Feb/2021 17:21:05] "[35m[1mPOST /addUser HTTP/1.1[0m" 500 -
[2021-02-18 17:21:09,773] ERROR in app: Exception on /updateUser [PATCH]
Traceback (most recent call last):
  File "/usr/local/lib/python3.6/dist-packages/flask/app.py", line 2447, in wsgi_app
    response = self.full_dispatch_request()
  File "/usr/local/lib/python3.6/dist-packages/flask/app.py", line 1952, in full_dispatch_request
    rv = self.handle_user_exception(e)
  File "/usr/local/lib/python3.6/dist-packages/flask/app.py", line 1821, in handle_user_exception
    reraise(exc_type, exc_value, tb)
  File "/usr/local/lib/python3.6/dist-packages/flask/_compat.py", line 39, in reraise
    raise value
  File "/usr/local/lib/python3.6/dist-packages/flask/app.py", line 1950, in full_dispatch_request
    rv = self.dispatch_request()
  File "/usr/local/lib/python3.6/dist-packages/flask/app.py", line 1936, in dispatch_request
    return self.view_functions[rule.endpoint](**req.view_args)
  File "runBackend.py", line 61, in updateUser
    res = dao.updateUser(dictOfUserAttrib)
AttributeError: 'UserDao' object has no attribute 'updateUser'
204.144.15.24 - - [18/Feb/2021 17:21:09] "[35m[1mPATCH /updateUser HTTP/1.1[0m" 500 -
[2021-02-18 17:21:12,210] ERROR in app: Exception on /deleteUser [DELETE]
Traceback (most recent call last):
  File "/root/green2go/Backend/userDao.py", line 58, in deleteUser
    mydb.commit()
NameError: name 'mydb' is not defined

During handling of the above exception, another exception occurred:

Traceback (most recent call last):
  File "/usr/local/lib/python3.6/dist-packages/flask/app.py", line 2447, in wsgi_app
    response = self.full_dispatch_request()
  File "/usr/local/lib/python3.6/dist-packages/flask/app.py", line 1952, in full_dispatch_request
    rv = self.handle_user_exception(e)
  File "/usr/local/lib/python3.6/dist-packages/flask/app.py", line 1821, in handle_user_exception
    reraise(exc_type, exc_value, tb)
  File "/usr/local/lib/python3.6/dist-packages/flask/_compat.py", line 39, in reraise
    raise value
  File "/usr/local/lib/python3.6/dist-packages/flask/app.py", line 1950, in full_dispatch_request
    rv = self.dispatch_request()
  File "/usr/local/lib/python3.6/dist-packages/flask/app.py", line 1936, in dispatch_request
    return self.view_functions[rule.endpoint](**req.view_args)
  File "runBackend.py", line 75, in deleteUser
    res = dao.deleteUser(email)
  File "/root/green2go/Backend/userDao.py", line 61, in deleteUser
    self.reconnectSql()
  File "/root/green2go/Backend/userDao.py", line 16, in reconnectSql
    database="sys")
  File "/usr/local/lib/python3.6/dist-packages/mysql/connector/__init__.py", line 179, in connect
    return MySQLConnection(*args, **kwargs)
  File "/usr/local/lib/python3.6/dist-packages/mysql/connector/connection.py", line 95, in __init__
    self.connect(**kwargs)
  File "/usr/local/lib/python3.6/dist-packages/mysql/connector/abstracts.py", line 716, in connect
    self._open_connection()
  File "/usr/local/lib/python3.6/dist-packages/mysql/connector/connection.py", line 207, in _open_connection
    self._do_handshake()
  File "/usr/local/lib/python3.6/dist-packages/mysql/connector/connection.py", line 101, in _do_handshake
    raise errors.get_exception(packet)
mysql.connector.errors.DatabaseError: 1040: Too many connections
204.144.15.24 - - [18/Feb/2021 17:21:12] "[35m[1mDELETE /deleteUser HTTP/1.1[0m" 500 -
[2021-02-18 17:21:16,346] ERROR in app: Exception on /getContainer [GET]
Traceback (most recent call last):
  File "/usr/local/lib/python3.6/dist-packages/flask/app.py", line 2447, in wsgi_app
    response = self.full_dispatch_request()
  File "/usr/local/lib/python3.6/dist-packages/flask/app.py", line 1953, in full_dispatch_request
    return self.finalize_request(rv)
  File "/usr/local/lib/python3.6/dist-packages/flask/app.py", line 1968, in finalize_request
    response = self.make_response(rv)
  File "/usr/local/lib/python3.6/dist-packages/flask/app.py", line 2098, in make_response
    "The view function did not return a valid response. The"
TypeError: The view function did not return a valid response. The function either returned None or ended without a return statement.
204.144.15.24 - - [18/Feb/2021 17:21:16] "[35m[1mGET /getContainer HTTP/1.1[0m" 500 -
204.144.15.24 - - [18/Feb/2021 17:23:07] "[37mGET /getUser HTTP/1.1[0m" 200 -
 * Serving Flask app "runBackend" (lazy loading)
 * Environment: production
   WARNING: This is a development server. Do not use it in a production deployment.
   Use a production WSGI server instead.
 * Debug mode: off
 * Running on http://0.0.0.0:5000/ (Press CTRL+C to quit)
204.144.15.24 - - [18/Feb/2021 17:50:38] "[37mGET /getUser HTTP/1.1[0m" 200 -
204.144.15.24 - - [18/Feb/2021 18:24:13] "[37mGET /getUser HTTP/1.1[0m" 200 -
204.144.15.24 - - [18/Feb/2021 18:24:16] "[37mPOST /addUser HTTP/1.1[0m" 200 -
204.144.15.24 - - [18/Feb/2021 18:25:43] "[37mPOST /addUser HTTP/1.1[0m" 200 -
204.144.15.24 - - [18/Feb/2021 18:27:11] "[37mPOST /addUser HTTP/1.1[0m" 200 -
204.144.15.24 - - [18/Feb/2021 18:30:22] "[37mPOST /addUser HTTP/1.1[0m" 200 -
34.86.35.8 - - [18/Feb/2021 19:39:43] "[33mGET / HTTP/1.1[0m" 404 -
54.86.50.139 - - [18/Feb/2021 19:45:35] "[37mPOST /addUser HTTP/1.1[0m" 200 -
54.86.50.139 - - [18/Feb/2021 19:45:40] "[37mPOST /addUser HTTP/1.1[0m" 200 -
54.86.50.139 - - [18/Feb/2021 19:46:14] "[37mPOST /addUser HTTP/1.1[0m" 200 -
54.86.50.139 - - [18/Feb/2021 19:46:19] "[37mPOST /addUser HTTP/1.1[0m" 200 -
34.96.130.78 - - [18/Feb/2021 20:22:59] "[33mGET / HTTP/1.1[0m" 404 -
204.144.15.24 - - [18/Feb/2021 21:38:36] "[37mGET /getUser HTTP/1.1[0m" 200 -
204.144.15.24 - - [18/Feb/2021 21:38:39] "[37mPOST /addUser HTTP/1.1[0m" 200 -
[2021-02-18 21:38:42,690] ERROR in app: Exception on /updateUser [PATCH]
Traceback (most recent call last):
  File "/usr/local/lib/python3.6/dist-packages/flask/app.py", line 2447, in wsgi_app
    response = self.full_dispatch_request()
  File "/usr/local/lib/python3.6/dist-packages/flask/app.py", line 1952, in full_dispatch_request
    rv = self.handle_user_exception(e)
  File "/usr/local/lib/python3.6/dist-packages/flask/app.py", line 1821, in handle_user_exception
    reraise(exc_type, exc_value, tb)
  File "/usr/local/lib/python3.6/dist-packages/flask/_compat.py", line 39, in reraise
    raise value
  File "/usr/local/lib/python3.6/dist-packages/flask/app.py", line 1950, in full_dispatch_request
    rv = self.dispatch_request()
  File "/usr/local/lib/python3.6/dist-packages/flask/app.py", line 1936, in dispatch_request
    return self.view_functions[rule.endpoint](**req.view_args)
  File "runBackend.py", line 61, in updateUser
    res = dao.updateUser(dictOfUserAttrib)
AttributeError: 'UserDao' object has no attribute 'updateUser'
204.144.15.24 - - [18/Feb/2021 21:38:42] "[35m[1mPATCH /updateUser HTTP/1.1[0m" 500 -
204.144.15.24 - - [18/Feb/2021 21:38:46] "[37mDELETE /deleteUser HTTP/1.1[0m" 200 -
[2021-02-18 21:39:00,821] ERROR in app: Exception on /getContainer [GET]
Traceback (most recent call last):
  File "/usr/local/lib/python3.6/dist-packages/flask/app.py", line 2447, in wsgi_app
    response = self.full_dispatch_request()
  File "/usr/local/lib/python3.6/dist-packages/flask/app.py", line 1953, in full_dispatch_request
    return self.finalize_request(rv)
  File "/usr/local/lib/python3.6/dist-packages/flask/app.py", line 1968, in finalize_request
    response = self.make_response(rv)
  File "/usr/local/lib/python3.6/dist-packages/flask/app.py", line 2098, in make_response
    "The view function did not return a valid response. The"
TypeError: The view function did not return a valid response. The function either returned None or ended without a return statement.
204.144.15.24 - - [18/Feb/2021 21:39:00] "[35m[1mGET /getContainer HTTP/1.1[0m" 500 -
[2021-02-18 21:39:03,972] ERROR in app: Exception on /addContainer [POST]
Traceback (most recent call last):
  File "/usr/local/lib/python3.6/dist-packages/flask/app.py", line 2447, in wsgi_app
    response = self.full_dispatch_request()
  File "/usr/local/lib/python3.6/dist-packages/flask/app.py", line 1952, in full_dispatch_request
    rv = self.handle_user_exception(e)
  File "/usr/local/lib/python3.6/dist-packages/flask/app.py", line 1821, in handle_user_exception
    reraise(exc_type, exc_value, tb)
  File "/usr/local/lib/python3.6/dist-packages/flask/_compat.py", line 39, in reraise
    raise value
  File "/usr/local/lib/python3.6/dist-packages/flask/app.py", line 1950, in full_dispatch_request
    rv = self.dispatch_request()
  File "/usr/local/lib/python3.6/dist-packages/flask/app.py", line 1936, in dispatch_request
    return self.view_functions[rule.endpoint](**req.view_args)
  File "runBackend.py", line 92, in addContainer
    res = dao2.addContainer(newContainer)
  File "/root/green2go/Backend/containerDao.py", line 16, in addContainer
    mycursor.execute(sql, val)
  File "/usr/local/lib/python3.6/dist-packages/mysql/connector/cursor.py", line 551, in execute
    self._handle_result(self._connection.cmd_query(stmt))
  File "/usr/local/lib/python3.6/dist-packages/mysql/connector/connection.py", line 490, in cmd_query
    result = self._handle_result(self._send_cmd(ServerCmd.QUERY, query))
  File "/usr/local/lib/python3.6/dist-packages/mysql/connector/connection.py", line 395, in _handle_result
    raise errors.get_exception(packet)
mysql.connector.errors.ProgrammingError: 1064 (42000): You have an error in your SQL syntax; check the manual that corresponds to your MySQL server version for the right syntax to use near '%s)' at line 1
204.144.15.24 - - [18/Feb/2021 21:39:03] "[35m[1mPOST /addContainer HTTP/1.1[0m" 500 -
[2021-02-18 21:39:06,802] ERROR in app: Exception on /updateContainer [PATCH]
Traceback (most recent call last):
  File "/usr/local/lib/python3.6/dist-packages/flask/app.py", line 2447, in wsgi_app
    response = self.full_dispatch_request()
  File "/usr/local/lib/python3.6/dist-packages/flask/app.py", line 1952, in full_dispatch_request
    rv = self.handle_user_exception(e)
  File "/usr/local/lib/python3.6/dist-packages/flask/app.py", line 1821, in handle_user_exception
    reraise(exc_type, exc_value, tb)
  File "/usr/local/lib/python3.6/dist-packages/flask/_compat.py", line 39, in reraise
    raise value
  File "/usr/local/lib/python3.6/dist-packages/flask/app.py", line 1950, in full_dispatch_request
    rv = self.dispatch_request()
  File "/usr/local/lib/python3.6/dist-packages/flask/app.py", line 1936, in dispatch_request
    return self.view_functions[rule.endpoint](**req.view_args)
  File "runBackend.py", line 134, in updateContainer
    res = dao2.updateContainer(dictOfContainerAttrib)
AttributeError: 'ContainerDao' object has no attribute 'updateContainer'
204.144.15.24 - - [18/Feb/2021 21:39:06] "[35m[1mPATCH /updateContainer HTTP/1.1[0m" 500 -
[2021-02-18 21:39:08,891] ERROR in app: Exception on /deleteContainer [DELETE]
Traceback (most recent call last):
  File "/usr/local/lib/python3.6/dist-packages/flask/app.py", line 2447, in wsgi_app
    response = self.full_dispatch_request()
  File "/usr/local/lib/python3.6/dist-packages/flask/app.py", line 1952, in full_dispatch_request
    rv = self.handle_user_exception(e)
  File "/usr/local/lib/python3.6/dist-packages/flask/app.py", line 1821, in handle_user_exception
    reraise(exc_type, exc_value, tb)
  File "/usr/local/lib/python3.6/dist-packages/flask/_compat.py", line 39, in reraise
    raise value
  File "/usr/local/lib/python3.6/dist-packages/flask/app.py", line 1950, in full_dispatch_request
    rv = self.dispatch_request()
  File "/usr/local/lib/python3.6/dist-packages/flask/app.py", line 1936, in dispatch_request
    return self.view_functions[rule.endpoint](**req.view_args)
  File "runBackend.py", line 121, in deleteContainer
    res = deleteContainer(qrcode)
TypeError: deleteContainer() takes 0 positional arguments but 1 was given
204.144.15.24 - - [18/Feb/2021 21:39:08] "[35m[1mDELETE /deleteContainer HTTP/1.1[0m" 500 -
 * Serving Flask app "runBackend" (lazy loading)
 * Environment: production
   WARNING: This is a development server. Do not use it in a production deployment.
   Use a production WSGI server instead.
 * Debug mode: off
 * Running on http://0.0.0.0:5000/ (Press CTRL+C to quit)
130.44.64.227 - - [18/Feb/2021 21:44:43] "[37mGET /getContainer HTTP/1.1[0m" 200 -
130.44.64.227 - - [18/Feb/2021 21:44:55] "[37mGET /getContainer HTTP/1.1[0m" 200 -
130.44.64.227 - - [18/Feb/2021 21:45:01] "[37mGET /getContainer HTTP/1.1[0m" 200 -
130.44.64.227 - - [18/Feb/2021 21:46:05] "[37mGET /getContainer HTTP/1.1[0m" 200 -
[2021-02-18 21:46:30,823] ERROR in app: Exception on /getContainer [GET]
Traceback (most recent call last):
  File "/usr/local/lib/python3.6/dist-packages/flask/app.py", line 2447, in wsgi_app
    response = self.full_dispatch_request()
  File "/usr/local/lib/python3.6/dist-packages/flask/app.py", line 1953, in full_dispatch_request
    return self.finalize_request(rv)
  File "/usr/local/lib/python3.6/dist-packages/flask/app.py", line 1968, in finalize_request
    response = self.make_response(rv)
  File "/usr/local/lib/python3.6/dist-packages/flask/app.py", line 2090, in make_response
    "The view function did not return a valid response tuple."
TypeError: The view function did not return a valid response tuple. The tuple must have the form (body, status, headers), (body, status), or (body, headers).
130.44.64.227 - - [18/Feb/2021 21:46:30] "[35m[1mGET /getContainer HTTP/1.1[0m" 500 -
130.44.64.227 - - [18/Feb/2021 21:46:43] "[37mGET /getContainer HTTP/1.1[0m" 200 -
[2021-02-18 21:47:10,734] ERROR in app: Exception on /getContainer [GET]
Traceback (most recent call last):
  File "/usr/local/lib/python3.6/dist-packages/flask/app.py", line 2447, in wsgi_app
    response = self.full_dispatch_request()
  File "/usr/local/lib/python3.6/dist-packages/flask/app.py", line 1953, in full_dispatch_request
    return self.finalize_request(rv)
  File "/usr/local/lib/python3.6/dist-packages/flask/app.py", line 1968, in finalize_request
    response = self.make_response(rv)
  File "/usr/local/lib/python3.6/dist-packages/flask/app.py", line 2090, in make_response
    "The view function did not return a valid response tuple."
TypeError: The view function did not return a valid response tuple. The tuple must have the form (body, status, headers), (body, status), or (body, headers).
130.44.64.227 - - [18/Feb/2021 21:47:10] "[35m[1mGET /getContainer HTTP/1.1[0m" 500 -
